Workbook

Sheet Tổng quan
A1: Checklist triển khai theo milestone M0 → M6 — Da Nang Connect (Giai đoạn 1)
A2: Trạng thái chụp ngày 19/09/2026. Đổi cột "Trạng thái" ở các sheet M0–M6, bảng dưới tự cập nhật. Xem sheet "Chú thích" để biết cách đọc và nguồn số liệu. Phân công 60-20-20 theo chức năng ngày 23/09/2026 (QĐ-78): xem sheet "Phân công". Cập nhật trạng thái các mục của TV3 ngày 03/10/2026 (sau khi chạy e2e thật).
A4: Phase | B4: Tên | C4: Ngày chốt | D4: Sprint | E4: Tổng mục | F4: Xong | G4: Một phần | H4: Chưa làm | I4: Bị chặn | J4: Cần chốt | K4: Chưa xác nhận | L4: Cắt / hoãn | M4: Tỷ lệ xong | N4: Mục tiêu | O4: Nếu trượt
A5: M0 | B5: Setup hạ tầng | C5: 18/09/2026 | D5: L0 | E5: =COUNTA(M0!$C$6:$C$400) -> 35 | F5: =COUNTIF(M0!$I$6:$I$400,"Xong") -> 9 | G5: =COUNTIF(M0!$I$6:$I$400,"Một phần") -> 5 | H5: =COUNTIF(M0!$I$6:$I$400,"Chưa làm") -> 10 | I5: =COUNTIF(M0!$I$6:$I$400,"Bị chặn") -> 0 | J5: =COUNTIF(M0!$I$6:$I$400,"Cần chốt") -> 1 | K5: =COUNTIF(M0!$I$6:$I$400,"Chưa xác nhận") -> 5 | L5: =COUNTIF(M0!$I$6:$I$400,"Cắt / hoãn") -> 5 | M5: =IFERROR(F5/(E5-L5),0) -> 0.3 | N5: L0 — 07/09 – 18/09/2026: Monorepo, Docker Compose, NestJS, Next.js, CI, khung i18n | O5: M0 trượt tối đa 3 ngày làm việc. Quá 3 ngày thì rút E1-S8 xuống mức script và đẩy phần còn lại vào S1 — không được để trượt lan sang M1 vì M1 nằm trên đường găng. Tinh gọn: Phương án script cho E1-S8 (còn 4 SP) đã được dùng sẵn, nên M0 không còn đòn bẩy hạ tải nào khác. Mọi phần trượt ăn thẳng vào L1, vốn đã xếp 32 SP story còn mở trên sức chứa 28.
A6: M1 | B6: API nền + Auth | C6: 02/10/2026 | D6: L1 | E6: =COUNTA('M1'!$C$6:$C$400) -> 49 | F6: =COUNTIF('M1'!$I$6:$I$400,"Xong") -> 11 | G6: =COUNTIF('M1'!$I$6:$I$400,"Một phần") -> 7 | H6: =COUNTIF('M1'!$I$6:$I$400,"Chưa làm") -> 18 | I6: =COUNTIF('M1'!$I$6:$I$400,"Bị chặn") -> 2 | J6: =COUNTIF('M1'!$I$6:$I$400,"Cần chốt") -> 6 | K6: =COUNTIF('M1'!$I$6:$I$400,"Chưa xác nhận") -> 2 | L6: =COUNTIF('M1'!$I$6:$I$400,"Cắt / hoãn") -> 3 | M6: =IFERROR(F6/(E6-L6),0) -> 0.23913043 | N6: L1 — 21/09 – 02/10/2026: Auth email + Google, refresh rotation, RBAC enum 5 role, trust_signals | O6: M1 không được trượt. Đây là mắt xích đường găng cứng nhất phía kỹ thuật — toàn bộ E3, E4, E6 đều chờ nó. Trượt M1 thì trượt hết. Phương án khẩn: cắt E2-S5 (Facebook) và E2-S6 (đặt lại mật khẩu) sang S2, dồn 2 người vào E2-S2 và E2-S9. Tinh gọn: E2-S4 và E2-S5 đã cắt, E2-S9 đã hoãn và E2-S2 đã xong, nên phương án khẩn là dời E1-S9 (Sentry chỉ cần trước khi staging có người dùng thật, tức beta L10) và E2-S6 sang L2, dồn TV2 vào E2-S1 và E2-S3 (Google trên web), TV1 hỗ trợ E2-S1 khi xong phần L0 còn tồn.
A7: M2 | B7: Tạo & khám phá sự kiện | C7: 13/11/2026 | D7: L2, L3, L4 | E7: =COUNTA('M2'!$C$6:$C$400) -> 72 | F7: =COUNTIF('M2'!$I$6:$I$400,"Xong") -> 0 | G7: =COUNTIF('M2'!$I$6:$I$400,"Một phần") -> 13 | H7: =COUNTIF('M2'!$I$6:$I$400,"Chưa làm") -> 43 | I7: =COUNTIF('M2'!$I$6:$I$400,"Bị chặn") -> 0 | J7: =COUNTIF('M2'!$I$6:$I$400,"Cần chốt") -> 5 | K7: =COUNTIF('M2'!$I$6:$I$400,"Chưa xác nhận") -> 1 | L7: =COUNTIF('M2'!$I$6:$I$400,"Cắt / hoãn") -> 10 | M7: =IFERROR(F7/(E7-L7),0) -> 0 | N7: L2 — 05/10 – 16/10/2026: Mô hình sự kiện + PostGIS + areas 6 khu vực MVP, hồ sơ cá nhân, ảnh qua dịch vụ có sẵn L3 — 19/10 – 30/10/2026: Tạo / sửa / huỷ sự kiện, form web một trang có tự lưu nháp, trang chi tiết + SEO/OG L4 — 02/11 – 13/11/2026: API lọc hyperlocal (khu vực · loại hình · thời gian · ngôn ngữ · phí), trang khám phá | O7: M2 đã có sẵn cơ chế ba nấc (§6.7). Nếu nấc 1 (web) trượt quá 1 tuần thì đây là điều kiện dừng cấp 1 — dừng nhận story mới, họp lại phạm vi trong 48 giờ, cân nhắc đòn bẩy 1 (thuê Mobile hợp đồng) hoặc rơi sang §10. Tinh gọn: M2 chỉ còn nấc web (M2+/M2++ hoãn cùng nhánh native) và không còn đòn bẩy thuê Mobile hợp đồng. Nếu L2–L4 trượt quá 1 tuần thì đòn bẩy phạm vi còn lại là nhóm C §10.2 (08:1608), chỉ áp khi Founder ký. Trong M2, nhóm C chỉ chạm E5-S3, mục mà NT-2 (08:1554) ghi giữ nguyên, nên phải giải mâu thuẫn này khi ký.
A8: M3 | B8: RSVP + Waitlist + Thông báo | C8: 11/12/2026 | D8: L5, L6 | E8: =COUNTA('M3'!$C$6:$C$400) -> 40 | F8: =COUNTIF('M3'!$I$6:$I$400,"Xong") -> 0 | G8: =COUNTIF('M3'!$I$6:$I$400,"Một phần") -> 4 | H8: =COUNTIF('M3'!$I$6:$I$400,"Chưa làm") -> 33 | I8: =COUNTIF('M3'!$I$6:$I$400,"Bị chặn") -> 0 | J8: =COUNTIF('M3'!$I$6:$I$400,"Cần chốt") -> 1 | K8: =COUNTIF('M3'!$I$6:$I$400,"Chưa xác nhận") -> 0 | L8: =COUNTIF('M3'!$I$6:$I$400,"Cắt / hoãn") -> 2 | M8: =IFERROR(F8/(E8-L8),0) -> 0 | N8: L5 — 16/11 – 27/11/2026: RSVP + sức chứa + WAITLIST, hàng đợi BullMQ L6 — 30/11 – 11/12/2026: Dịch vụ thông báo, email, nhắc T‑24h và T‑2h, Web Push cho PWA | O8: M3-3 (waitlist) là MUST của MVP, không được hoãn. Nếu tuần W09 kết thúc mà E6-S3 chưa xong, cắt ngay E5-S7 khỏi S4 và dồn toàn bộ nhánh backend vào RSVP. Nấc M2+ lùi sang S5. Tinh gọn: E5-S7 đã hoãn theo nhóm A nên không còn story mobile để cắt thay. Nếu hết L5 (27/11/2026) mà E6-S3 chưa xong thì dời MK-MY-01, MK-MY-02 và MK-MY-03 (đều là việc của TV1: GET /me/agenda, giữ chỗ 12 giờ, .ics feed) ra khỏi M3 để TV1 dồn sức vào waitlist; MK-RSVP-01 chỉ là việc web nên giữ lại. L6 còn trống khoảng 7 SP để nhận phần dời từ L5. Không dùng nhóm C để bù (chỉ dùng khi buộc giữ ngày 18/03/2027, 08:1558). Mốc M3 vẫn là 11/12/2026.
A9: M4 | B9: Trust & Safety tối thiểu | C9: 25/12/2026 | D9: L7 | E9: =COUNTA('M4'!$C$6:$C$400) -> 40 | F9: =COUNTIF('M4'!$I$6:$I$400,"Xong") -> 5 | G9: =COUNTIF('M4'!$I$6:$I$400,"Một phần") -> 9 | H9: =COUNTIF('M4'!$I$6:$I$400,"Chưa làm") -> 21 | I9: =COUNTIF('M4'!$I$6:$I$400,"Bị chặn") -> 0 | J9: =COUNTIF('M4'!$I$6:$I$400,"Cần chốt") -> 2 | K9: =COUNTIF('M4'!$I$6:$I$400,"Chưa xác nhận") -> 0 | L9: =COUNTIF('M4'!$I$6:$I$400,"Cắt / hoãn") -> 3 | M9: =IFERROR(F9/(E9-L9),0) -> 0.13513514 | N9: L7 — 14/12 – 25/12/2026: Trust & Safety: report, block, xử lý kiểm duyệt, trust level T0–T3 tự động | O9: M4-8 và M4-9 là điều kiện chặn cứng để mở beta — không có chính sách đã thẩm định thì không được thu thập dữ liệu của 100 người thật. Nếu luật sư chưa xác nhận kịp, lùi ngày mời beta wave 1 chứ không mở beta bằng bản thảo chưa thẩm định. Tinh gọn: beta kín còn 60 người, mở ở L10 (15/02/2027); M4-8 và M4-9 vẫn là điều kiện chặn cứng, luật sư xác nhận trễ thì lùi mời beta wave 1 và M5 (26/02/2027) trượt theo. Story M4 trượt khỏi L7 thì không có chỗ đệm: sau 25/12 là tuần đóng băng 28/12 – 01/01, rồi L8 đã kín 28 SP cho Admin Curation Console (NT-1, không cắt).
A10: M5 | B10: Beta kín 60 user | C10: 26/02/2027 | D10: L8, L9, L10 | E10: =COUNTA('M5'!$C$6:$C$400) -> 64 | F10: =COUNTIF('M5'!$I$6:$I$400,"Xong") -> 1 | G10: =COUNTIF('M5'!$I$6:$I$400,"Một phần") -> 0 | H10: =COUNTIF('M5'!$I$6:$I$400,"Chưa làm") -> 57 | I10: =COUNTIF('M5'!$I$6:$I$400,"Bị chặn") -> 0 | J10: =COUNTIF('M5'!$I$6:$I$400,"Cần chốt") -> 0 | K10: =COUNTIF('M5'!$I$6:$I$400,"Chưa xác nhận") -> 0 | L10: =COUNTIF('M5'!$I$6:$I$400,"Cắt / hoãn") -> 6 | M10: =IFERROR(F10/(E10-L10),0) -> 0.017241379 | N10: L8 — 04/01 – 15/01/2027: Admin Curation Console + luồng chuyển giao organizer (NT-1, không cắt) L9 — 18/01 – 29/01/2027: PWA: manifest, service worker, add-to-home, tối ưu điện thoại; xuất & xoá dữ liệu cá nhân L10 — 15/02 – 26/02/2027: Beta kín 60 user (giảm từ 100 vì không còn kênh cửa hàng ứng dụng), trực hotfix hằng ngày | O10: M5 có 2 tuần đệm tự nhiên (đóng băng cuối năm + S8). Nếu M5-7 trượt vì Play closed testing bắt đầu muộn thì đây là rủi ro chặn M6 — xem §8.3. Tinh gọn: Không còn 2 tuần đệm, và M5-7 đã hoãn cùng E12. Đóng băng Tết 01–12/02/2027 nằm giữa L9 và L10 nên E8-S7, PWA và thư xác nhận Privacy Policy của luật sư (M4-9) phải xong trong L9. M5 trượt thì M6 01/04/2027 trượt theo, vì L11 bắt đầu ngay 01/03/2027.
A11: M6 | B11: Ra mắt công khai | C11: 01/04/2027 | D11: L11, L12 | E11: =COUNTA('M6'!$C$6:$C$400) -> 54 | F11: =COUNTIF('M6'!$I$6:$I$400,"Xong") -> 0 | G11: =COUNTIF('M6'!$I$6:$I$400,"Một phần") -> 0 | H11: =COUNTIF('M6'!$I$6:$I$400,"Chưa làm") -> 36 | I11: =COUNTIF('M6'!$I$6:$I$400,"Bị chặn") -> 0 | J11: =COUNTIF('M6'!$I$6:$I$400,"Cần chốt") -> 0 | K11: =COUNTIF('M6'!$I$6:$I$400,"Chưa xác nhận") -> 0 | L11: =COUNTIF('M6'!$I$6:$I$400,"Cắt / hoãn") -> 18 | M11: =IFERROR(F11/(E11-L11),0) -> 0 | N11: L11 — 01/03 – 12/03/2027: Sửa lỗi beta P0/P1, nạp bản dịch tiếng Việt thuê ngoài, bịt hai chỗ rớt phễu lớn nhất L12 — 15/03 – 26/03/2027: SEO, diễn tập runbook, release candidate, đẩy curate lên 25 sự kiện/tuần | O11: không ra mắt công khai đúng hạn. Lùi ra mắt 2–4 tuần và dồn toàn bộ nguồn lực vào curate + chuyển giao organizer. Ra mắt với một ứng dụng trông đầy nhưng không có dòng chảy là kịch bản hỏng tệ nhất: người dùng mở lần đầu, không thấy gì đáng đi, và không quay lại — không có lần ra mắt thứ hai với cùng một người. Tinh gọn: Không có đệm tiền để lùi lâu (08:1540: sai thì phải gọi vốn hoặc dừng) và ngưỡng dòng chảy không được làm mềm (08:1688), nên trượt gate nghĩa là giả thuyết sai chứ không phải do thiếu tính năng. L11–L12 chỉ xếp 18 SP story trên sức chứa 51; phần dư là đệm sửa lỗi beta, không dùng để thêm tính năng.
A12: Tổng | E12: =SUM(E5:E11) -> 354 | F12: =SUM(F5:F11) -> 26 | G12: =SUM(G5:G11) -> 38 | H12: =SUM(H5:H11) -> 218 | I12: =SUM(I5:I11) -> 2 | J12: =SUM(J5:J11) -> 15 | K12: =SUM(K5:K11) -> 8 | L12: =SUM(L5:L11) -> 47 | M12: =IFERROR(F12/(E12-L12),0) -> 0.084690554

Sheet Phân công
A1: Phân công 60-20-20 theo chức năng (QĐ-78, 23/09/2026)
A2: Tự tính lại từ cột Phụ trách, SP và Trạng thái của các sheet M0–M6. Người đứng tên đầu ở cột Phụ trách nhận SP. SP còn lại = mục chưa Xong và không Cắt / hoãn (mục Một phần tính đủ SP). Việc của Founder và Thuê ngoài không tính.
A4: Thành viên | B4: Chức năng sở hữu | C4: SP còn lại | D4: Tỉ lệ còn lại | E4: Mục tiêu | F4: SP trong phạm vi (gồm đã xong) | G4: Mục đứng đầu
A5: TV1 (dùng AI) | B5: Nền tảng và Tech Lead · Phân quyền RBAC và trust · Sự kiện · Khám phá · RSVP và waitlist · Thông báo · Đo lường sản phẩm | C5: =SUMIFS(M0!$G$6:$G$400,M0!$F$6:$F$400,"TV1*",M0!$I$6:$I$400,"<>Cắt / hoãn",M0!$I$6:$I$400,"<>Xong")+SUMIFS('M1'!$G$6:$G$400,'M1'!$F$6:$F$400,"TV1*",'M1'!$I$6:$I$400,"<>Cắt / hoãn",'M1'!$I$6:$I$400,"<>Xong")+SUMIFS('M2'!$G$6:$G$400,'M2'!$F$6:$F$400,"TV1*",'M2'!$I$6:$I$400,"<>Cắt / hoãn",'M2'!$I$6:$I$400,"<>Xong")+SUMIFS('M3'!$G$6:$G$400,'M3'!$F$6:$F$400,"TV1*",'M3'!$I$6:$I$400,"<>Cắt / hoãn",'M3'!$I$6:$I$400,"<>Xong")+SUMIFS('M4'!$G$6:$G$400,'M4'!$F$6:$F$400,"TV1*",'M4'!$I$6:$I$400,"<>Cắt / hoãn",'M4'!$I$6:$I$400,"<>Xong")+SUMIFS('M5'!$G$6:$G$400,'M5'!$F$6:$F$400,"TV1*",'M5'!$I$6:$I$400,"<>Cắt / hoãn",'M5'!$I$6:$I$400,"<>Xong")+SUMIFS('M6'!$G$6:$G$400,'M6'!$F$6:$F$400,"TV1*",'M6'!$I$6:$I$400,"<>Cắt / hoãn",'M6'!$I$6:$I$400,"<>Xong") -> 188 | D5: =IFERROR(C5/C$8,0) -> 0.5875 | E5: 0.6 | F5: =SUMIFS(M0!$G$6:$G$400,M0!$F$6:$F$400,"TV1*",M0!$I$6:$I$400,"<>Cắt / hoãn")+SUMIFS('M1'!$G$6:$G$400,'M1'!$F$6:$F$400,"TV1*",'M1'!$I$6:$I$400,"<>Cắt / hoãn")+SUMIFS('M2'!$G$6:$G$400,'M2'!$F$6:$F$400,"TV1*",'M2'!$I$6:$I$400,"<>Cắt / hoãn")+SUMIFS('M3'!$G$6:$G$400,'M3'!$F$6:$F$400,"TV1*",'M3'!$I$6:$I$400,"<>Cắt / hoãn")+SUMIFS('M4'!$G$6:$G$400,'M4'!$F$6:$F$400,"TV1*",'M4'!$I$6:$I$400,"<>Cắt / hoãn")+SUMIFS('M5'!$G$6:$G$400,'M5'!$F$6:$F$400,"TV1*",'M5'!$I$6:$I$400,"<>Cắt / hoãn")+SUMIFS('M6'!$G$6:$G$400,'M6'!$F$6:$F$400,"TV1*",'M6'!$I$6:$I$400,"<>Cắt / hoãn") -> 213 | G5: =COUNTIFS(M0!$F$6:$F$400,"TV1*",M0!$I$6:$I$400,"<>Cắt / hoãn")+COUNTIFS('M1'!$F$6:$F$400,"TV1*",'M1'!$I$6:$I$400,"<>Cắt / hoãn")+COUNTIFS('M2'!$F$6:$F$400,"TV1*",'M2'!$I$6:$I$400,"<>Cắt / hoãn")+COUNTIFS('M3'!$F$6:$F$400,"TV1*",'M3'!$I$6:$I$400,"<>Cắt / hoãn")+COUNTIFS('M4'!$F$6:$F$400,"TV1*",'M4'!$I$6:$I$400,"<>Cắt / hoãn")+COUNTIFS('M5'!$F$6:$F$400,"TV1*",'M5'!$I$6:$I$400,"<>Cắt / hoãn")+COUNTIFS('M6'!$F$6:$F$400,"TV1*",'M6'!$I$6:$I$400,"<>Cắt / hoãn") -> 161
A6: TV2 | B6: Tài khoản và phiên · Hồ sơ, onboarding, ảnh/CDN, OTP · Ngôn ngữ và i18n, tuỳ chọn thông báo, xuất/xoá dữ liệu · PWA và SEO toàn site | C6: =SUMIFS(M0!$G$6:$G$400,M0!$F$6:$F$400,"TV2*",M0!$I$6:$I$400,"<>Cắt / hoãn",M0!$I$6:$I$400,"<>Xong")+SUMIFS('M1'!$G$6:$G$400,'M1'!$F$6:$F$400,"TV2*",'M1'!$I$6:$I$400,"<>Cắt / hoãn",'M1'!$I$6:$I$400,"<>Xong")+SUMIFS('M2'!$G$6:$G$400,'M2'!$F$6:$F$400,"TV2*",'M2'!$I$6:$I$400,"<>Cắt / hoãn",'M2'!$I$6:$I$400,"<>Xong")+SUMIFS('M3'!$G$6:$G$400,'M3'!$F$6:$F$400,"TV2*",'M3'!$I$6:$I$400,"<>Cắt / hoãn",'M3'!$I$6:$I$400,"<>Xong")+SUMIFS('M4'!$G$6:$G$400,'M4'!$F$6:$F$400,"TV2*",'M4'!$I$6:$I$400,"<>Cắt / hoãn",'M4'!$I$6:$I$400,"<>Xong")+SUMIFS('M5'!$G$6:$G$400,'M5'!$F$6:$F$400,"TV2*",'M5'!$I$6:$I$400,"<>Cắt / hoãn",'M5'!$I$6:$I$400,"<>Xong")+SUMIFS('M6'!$G$6:$G$400,'M6'!$F$6:$F$400,"TV2*",'M6'!$I$6:$I$400,"<>Cắt / hoãn",'M6'!$I$6:$I$400,"<>Xong") -> 67 | D6: =IFERROR(C6/C$8,0) -> 0.209375 | E6: 0.2 | F6: =SUMIFS(M0!$G$6:$G$400,M0!$F$6:$F$400,"TV2*",M0!$I$6:$I$400,"<>Cắt / hoãn")+SUMIFS('M1'!$G$6:$G$400,'M1'!$F$6:$F$400,"TV2*",'M1'!$I$6:$I$400,"<>Cắt / hoãn")+SUMIFS('M2'!$G$6:$G$400,'M2'!$F$6:$F$400,"TV2*",'M2'!$I$6:$I$400,"<>Cắt / hoãn")+SUMIFS('M3'!$G$6:$G$400,'M3'!$F$6:$F$400,"TV2*",'M3'!$I$6:$I$400,"<>Cắt / hoãn")+SUMIFS('M4'!$G$6:$G$400,'M4'!$F$6:$F$400,"TV2*",'M4'!$I$6:$I$400,"<>Cắt / hoãn")+SUMIFS('M5'!$G$6:$G$400,'M5'!$F$6:$F$400,"TV2*",'M5'!$I$6:$I$400,"<>Cắt / hoãn")+SUMIFS('M6'!$G$6:$G$400,'M6'!$F$6:$F$400,"TV2*",'M6'!$I$6:$I$400,"<>Cắt / hoãn") -> 78 | G6: =COUNTIFS(M0!$F$6:$F$400,"TV2*",M0!$I$6:$I$400,"<>Cắt / hoãn")+COUNTIFS('M1'!$F$6:$F$400,"TV2*",'M1'!$I$6:$I$400,"<>Cắt / hoãn")+COUNTIFS('M2'!$F$6:$F$400,"TV2*",'M2'!$I$6:$I$400,"<>Cắt / hoãn")+COUNTIFS('M3'!$F$6:$F$400,"TV2*",'M3'!$I$6:$I$400,"<>Cắt / hoãn")+COUNTIFS('M4'!$F$6:$F$400,"TV2*",'M4'!$I$6:$I$400,"<>Cắt / hoãn")+COUNTIFS('M5'!$F$6:$F$400,"TV2*",'M5'!$I$6:$I$400,"<>Cắt / hoãn")+COUNTIFS('M6'!$F$6:$F$400,"TV2*",'M6'!$I$6:$I$400,"<>Cắt / hoãn") -> 46
A7: TV3 | B7: Khu vực · Kiểm duyệt và chống spam · Admin Console, curate và nhận quyền · Tin tức do đội vận hành đăng · Phễu phân tích | C7: =SUMIFS(M0!$G$6:$G$400,M0!$F$6:$F$400,"TV3*",M0!$I$6:$I$400,"<>Cắt / hoãn",M0!$I$6:$I$400,"<>Xong")+SUMIFS('M1'!$G$6:$G$400,'M1'!$F$6:$F$400,"TV3*",'M1'!$I$6:$I$400,"<>Cắt / hoãn",'M1'!$I$6:$I$400,"<>Xong")+SUMIFS('M2'!$G$6:$G$400,'M2'!$F$6:$F$400,"TV3*",'M2'!$I$6:$I$400,"<>Cắt / hoãn",'M2'!$I$6:$I$400,"<>Xong")+SUMIFS('M3'!$G$6:$G$400,'M3'!$F$6:$F$400,"TV3*",'M3'!$I$6:$I$400,"<>Cắt / hoãn",'M3'!$I$6:$I$400,"<>Xong")+SUMIFS('M4'!$G$6:$G$400,'M4'!$F$6:$F$400,"TV3*",'M4'!$I$6:$I$400,"<>Cắt / hoãn",'M4'!$I$6:$I$400,"<>Xong")+SUMIFS('M5'!$G$6:$G$400,'M5'!$F$6:$F$400,"TV3*",'M5'!$I$6:$I$400,"<>Cắt / hoãn",'M5'!$I$6:$I$400,"<>Xong")+SUMIFS('M6'!$G$6:$G$400,'M6'!$F$6:$F$400,"TV3*",'M6'!$I$6:$I$400,"<>Cắt / hoãn",'M6'!$I$6:$I$400,"<>Xong") -> 65 | D7: =IFERROR(C7/C$8,0) -> 0.203125 | E7: 0.2 | F7: =SUMIFS(M0!$G$6:$G$400,M0!$F$6:$F$400,"TV3*",M0!$I$6:$I$400,"<>Cắt / hoãn")+SUMIFS('M1'!$G$6:$G$400,'M1'!$F$6:$F$400,"TV3*",'M1'!$I$6:$I$400,"<>Cắt / hoãn")+SUMIFS('M2'!$G$6:$G$400,'M2'!$F$6:$F$400,"TV3*",'M2'!$I$6:$I$400,"<>Cắt / hoãn")+SUMIFS('M3'!$G$6:$G$400,'M3'!$F$6:$F$400,"TV3*",'M3'!$I$6:$I$400,"<>Cắt / hoãn")+SUMIFS('M4'!$G$6:$G$400,'M4'!$F$6:$F$400,"TV3*",'M4'!$I$6:$I$400,"<>Cắt / hoãn")+SUMIFS('M5'!$G$6:$G$400,'M5'!$F$6:$F$400,"TV3*",'M5'!$I$6:$I$400,"<>Cắt / hoãn")+SUMIFS('M6'!$G$6:$G$400,'M6'!$F$6:$F$400,"TV3*",'M6'!$I$6:$I$400,"<>Cắt / hoãn") -> 65 | G7: =COUNTIFS(M0!$F$6:$F$400,"TV3*",M0!$I$6:$I$400,"<>Cắt / hoãn")+COUNTIFS('M1'!$F$6:$F$400,"TV3*",'M1'!$I$6:$I$400,"<>Cắt / hoãn")+COUNTIFS('M2'!$F$6:$F$400,"TV3*",'M2'!$I$6:$I$400,"<>Cắt / hoãn")+COUNTIFS('M3'!$F$6:$F$400,"TV3*",'M3'!$I$6:$I$400,"<>Cắt / hoãn")+COUNTIFS('M4'!$F$6:$F$400,"TV3*",'M4'!$I$6:$I$400,"<>Cắt / hoãn")+COUNTIFS('M5'!$F$6:$F$400,"TV3*",'M5'!$I$6:$I$400,"<>Cắt / hoãn")+COUNTIFS('M6'!$F$6:$F$400,"TV3*",'M6'!$I$6:$I$400,"<>Cắt / hoãn") -> 31
A8: Tổng | C8: =SUM(C5:C7) -> 320 | D8: =SUM(D5:D7) -> 1 | E8: =SUM(E5:E7) -> 1 | F8: =SUM(F5:F7) -> 356 | G8: =SUM(G5:G7) -> 238
A10: SP còn lại theo sprint (theo cột Sprint hiện tại, chưa dời lịch)
A11: Sprint | B11: TV1 | C11: TV2 | D11: TV3 | E11: Tổng
A12: L0 | B12: =SUMIFS(M0!$G$6:$G$400,M0!$F$6:$F$400,"TV1*",M0!$I$6:$I$400,"<>Cắt / hoãn",M0!$I$6:$I$400,"<>Xong") -> 14 | C12: =SUMIFS(M0!$G$6:$G$400,M0!$F$6:$F$400,"TV2*",M0!$I$6:$I$400,"<>Cắt / hoãn",M0!$I$6:$I$400,"<>Xong") -> 0 | D12: =SUMIFS(M0!$G$6:$G$400,M0!$F$6:$F$400,"TV3*",M0!$I$6:$I$400,"<>Cắt / hoãn",M0!$I$6:$I$400,"<>Xong") -> 0 | E12: =SUM(B12:D12) -> 14
A13: L1 | B13: =SUMIFS('M1'!$G$6:$G$400,'M1'!$F$6:$F$400,"TV1*",'M1'!$I$6:$I$400,"<>Cắt / hoãn",'M1'!$I$6:$I$400,"<>Xong") -> 3 | C13: =SUMIFS('M1'!$G$6:$G$400,'M1'!$F$6:$F$400,"TV2*",'M1'!$I$6:$I$400,"<>Cắt / hoãn",'M1'!$I$6:$I$400,"<>Xong") -> 24 | D13: =SUMIFS('M1'!$G$6:$G$400,'M1'!$F$6:$F$400,"TV3*",'M1'!$I$6:$I$400,"<>Cắt / hoãn",'M1'!$I$6:$I$400,"<>Xong") -> 0 | E13: =SUM(B13:D13) -> 27
A14: L2 | B14: =SUMIFS('M2'!$G$6:$G$400,'M2'!$F$6:$F$400,"TV1*",'M2'!$I$6:$I$400,"<>Cắt / hoãn",'M2'!$I$6:$I$400,"<>Xong",'M2'!$E$6:$E$400,"L2")+SUMIFS('M3'!$G$6:$G$400,'M3'!$F$6:$F$400,"TV1*",'M3'!$I$6:$I$400,"<>Cắt / hoãn",'M3'!$I$6:$I$400,"<>Xong",'M3'!$E$6:$E$400,"L2")+SUMIFS('M4'!$G$6:$G$400,'M4'!$F$6:$F$400,"TV1*",'M4'!$I$6:$I$400,"<>Cắt / hoãn",'M4'!$I$6:$I$400,"<>Xong",'M4'!$E$6:$E$400,"L2")+SUMIFS('M5'!$G$6:$G$400,'M5'!$F$6:$F$400,"TV1*",'M5'!$I$6:$I$400,"<>Cắt / hoãn",'M5'!$I$6:$I$400,"<>Xong",'M5'!$E$6:$E$400,"L2")+SUMIFS('M6'!$G$6:$G$400,'M6'!$F$6:$F$400,"TV1*",'M6'!$I$6:$I$400,"<>Cắt / hoãn",'M6'!$I$6:$I$400,"<>Xong",'M6'!$E$6:$E$400,"L2") -> 13 | C14: =SUMIFS('M2'!$G$6:$G$400,'M2'!$F$6:$F$400,"TV2*",'M2'!$I$6:$I$400,"<>Cắt / hoãn",'M2'!$I$6:$I$400,"<>Xong",'M2'!$E$6:$E$400,"L2")+SUMIFS('M3'!$G$6:$G$400,'M3'!$F$6:$F$400,"TV2*",'M3'!$I$6:$I$400,"<>Cắt / hoãn",'M3'!$I$6:$I$400,"<>Xong",'M3'!$E$6:$E$400,"L2")+SUMIFS('M4'!$G$6:$G$400,'M4'!$F$6:$F$400,"TV2*",'M4'!$I$6:$I$400,"<>Cắt / hoãn",'M4'!$I$6:$I$400,"<>Xong",'M4'!$E$6:$E$400,"L2")+SUMIFS('M5'!$G$6:$G$400,'M5'!$F$6:$F$400,"TV2*",'M5'!$I$6:$I$400,"<>Cắt / hoãn",'M5'!$I$6:$I$400,"<>Xong",'M5'!$E$6:$E$400,"L2")+SUMIFS('M6'!$G$6:$G$400,'M6'!$F$6:$F$400,"TV2*",'M6'!$I$6:$I$400,"<>Cắt / hoãn",'M6'!$I$6:$I$400,"<>Xong",'M6'!$E$6:$E$400,"L2") -> 16 | D14: =SUMIFS('M2'!$G$6:$G$400,'M2'!$F$6:$F$400,"TV3*",'M2'!$I$6:$I$400,"<>Cắt / hoãn",'M2'!$I$6:$I$400,"<>Xong",'M2'!$E$6:$E$400,"L2")+SUMIFS('M3'!$G$6:$G$400,'M3'!$F$6:$F$400,"TV3*",'M3'!$I$6:$I$400,"<>Cắt / hoãn",'M3'!$I$6:$I$400,"<>Xong",'M3'!$E$6:$E$400,"L2")+SUMIFS('M4'!$G$6:$G$400,'M4'!$F$6:$F$400,"TV3*",'M4'!$I$6:$I$400,"<>Cắt / hoãn",'M4'!$I$6:$I$400,"<>Xong",'M4'!$E$6:$E$400,"L2")+SUMIFS('M5'!$G$6:$G$400,'M5'!$F$6:$F$400,"TV3*",'M5'!$I$6:$I$400,"<>Cắt / hoãn",'M5'!$I$6:$I$400,"<>Xong",'M5'!$E$6:$E$400,"L2")+SUMIFS('M6'!$G$6:$G$400,'M6'!$F$6:$F$400,"TV3*",'M6'!$I$6:$I$400,"<>Cắt / hoãn",'M6'!$I$6:$I$400,"<>Xong",'M6'!$E$6:$E$400,"L2") -> 5 | E14: =SUM(B14:D14) -> 34
A15: L3 | B15: =SUMIFS('M2'!$G$6:$G$400,'M2'!$F$6:$F$400,"TV1*",'M2'!$I$6:$I$400,"<>Cắt / hoãn",'M2'!$I$6:$I$400,"<>Xong",'M2'!$E$6:$E$400,"L3")+SUMIFS('M3'!$G$6:$G$400,'M3'!$F$6:$F$400,"TV1*",'M3'!$I$6:$I$400,"<>Cắt / hoãn",'M3'!$I$6:$I$400,"<>Xong",'M3'!$E$6:$E$400,"L3")+SUMIFS('M4'!$G$6:$G$400,'M4'!$F$6:$F$400,"TV1*",'M4'!$I$6:$I$400,"<>Cắt / hoãn",'M4'!$I$6:$I$400,"<>Xong",'M4'!$E$6:$E$400,"L3")+SUMIFS('M5'!$G$6:$G$400,'M5'!$F$6:$F$400,"TV1*",'M5'!$I$6:$I$400,"<>Cắt / hoãn",'M5'!$I$6:$I$400,"<>Xong",'M5'!$E$6:$E$400,"L3")+SUMIFS('M6'!$G$6:$G$400,'M6'!$F$6:$F$400,"TV1*",'M6'!$I$6:$I$400,"<>Cắt / hoãn",'M6'!$I$6:$I$400,"<>Xong",'M6'!$E$6:$E$400,"L3") -> 29 | C15: =SUMIFS('M2'!$G$6:$G$400,'M2'!$F$6:$F$400,"TV2*",'M2'!$I$6:$I$400,"<>Cắt / hoãn",'M2'!$I$6:$I$400,"<>Xong",'M2'!$E$6:$E$400,"L3")+SUMIFS('M3'!$G$6:$G$400,'M3'!$F$6:$F$400,"TV2*",'M3'!$I$6:$I$400,"<>Cắt / hoãn",'M3'!$I$6:$I$400,"<>Xong",'M3'!$E$6:$E$400,"L3")+SUMIFS('M4'!$G$6:$G$400,'M4'!$F$6:$F$400,"TV2*",'M4'!$I$6:$I$400,"<>Cắt / hoãn",'M4'!$I$6:$I$400,"<>Xong",'M4'!$E$6:$E$400,"L3")+SUMIFS('M5'!$G$6:$G$400,'M5'!$F$6:$F$400,"TV2*",'M5'!$I$6:$I$400,"<>Cắt / hoãn",'M5'!$I$6:$I$400,"<>Xong",'M5'!$E$6:$E$400,"L3")+SUMIFS('M6'!$G$6:$G$400,'M6'!$F$6:$F$400,"TV2*",'M6'!$I$6:$I$400,"<>Cắt / hoãn",'M6'!$I$6:$I$400,"<>Xong",'M6'!$E$6:$E$400,"L3") -> 0 | D15: =SUMIFS('M2'!$G$6:$G$400,'M2'!$F$6:$F$400,"TV3*",'M2'!$I$6:$I$400,"<>Cắt / hoãn",'M2'!$I$6:$I$400,"<>Xong",'M2'!$E$6:$E$400,"L3")+SUMIFS('M3'!$G$6:$G$400,'M3'!$F$6:$F$400,"TV3*",'M3'!$I$6:$I$400,"<>Cắt / hoãn",'M3'!$I$6:$I$400,"<>Xong",'M3'!$E$6:$E$400,"L3")+SUMIFS('M4'!$G$6:$G$400,'M4'!$F$6:$F$400,"TV3*",'M4'!$I$6:$I$400,"<>Cắt / hoãn",'M4'!$I$6:$I$400,"<>Xong",'M4'!$E$6:$E$400,"L3")+SUMIFS('M5'!$G$6:$G$400,'M5'!$F$6:$F$400,"TV3*",'M5'!$I$6:$I$400,"<>Cắt / hoãn",'M5'!$I$6:$I$400,"<>Xong",'M5'!$E$6:$E$400,"L3")+SUMIFS('M6'!$G$6:$G$400,'M6'!$F$6:$F$400,"TV3*",'M6'!$I$6:$I$400,"<>Cắt / hoãn",'M6'!$I$6:$I$400,"<>Xong",'M6'!$E$6:$E$400,"L3") -> 0 | E15: =SUM(B15:D15) -> 29
A16: L4 | B16: =SUMIFS('M2'!$G$6:$G$400,'M2'!$F$6:$F$400,"TV1*",'M2'!$I$6:$I$400,"<>Cắt / hoãn",'M2'!$I$6:$I$400,"<>Xong",'M2'!$E$6:$E$400,"L4")+SUMIFS('M3'!$G$6:$G$400,'M3'!$F$6:$F$400,"TV1*",'M3'!$I$6:$I$400,"<>Cắt / hoãn",'M3'!$I$6:$I$400,"<>Xong",'M3'!$E$6:$E$400,"L4")+SUMIFS('M4'!$G$6:$G$400,'M4'!$F$6:$F$400,"TV1*",'M4'!$I$6:$I$400,"<>Cắt / hoãn",'M4'!$I$6:$I$400,"<>Xong",'M4'!$E$6:$E$400,"L4")+SUMIFS('M5'!$G$6:$G$400,'M5'!$F$6:$F$400,"TV1*",'M5'!$I$6:$I$400,"<>Cắt / hoãn",'M5'!$I$6:$I$400,"<>Xong",'M5'!$E$6:$E$400,"L4")+SUMIFS('M6'!$G$6:$G$400,'M6'!$F$6:$F$400,"TV1*",'M6'!$I$6:$I$400,"<>Cắt / hoãn",'M6'!$I$6:$I$400,"<>Xong",'M6'!$E$6:$E$400,"L4") -> 35 | C16: =SUMIFS('M2'!$G$6:$G$400,'M2'!$F$6:$F$400,"TV2*",'M2'!$I$6:$I$400,"<>Cắt / hoãn",'M2'!$I$6:$I$400,"<>Xong",'M2'!$E$6:$E$400,"L4")+SUMIFS('M3'!$G$6:$G$400,'M3'!$F$6:$F$400,"TV2*",'M3'!$I$6:$I$400,"<>Cắt / hoãn",'M3'!$I$6:$I$400,"<>Xong",'M3'!$E$6:$E$400,"L4")+SUMIFS('M4'!$G$6:$G$400,'M4'!$F$6:$F$400,"TV2*",'M4'!$I$6:$I$400,"<>Cắt / hoãn",'M4'!$I$6:$I$400,"<>Xong",'M4'!$E$6:$E$400,"L4")+SUMIFS('M5'!$G$6:$G$400,'M5'!$F$6:$F$400,"TV2*",'M5'!$I$6:$I$400,"<>Cắt / hoãn",'M5'!$I$6:$I$400,"<>Xong",'M5'!$E$6:$E$400,"L4")+SUMIFS('M6'!$G$6:$G$400,'M6'!$F$6:$F$400,"TV2*",'M6'!$I$6:$I$400,"<>Cắt / hoãn",'M6'!$I$6:$I$400,"<>Xong",'M6'!$E$6:$E$400,"L4") -> 0 | D16: =SUMIFS('M2'!$G$6:$G$400,'M2'!$F$6:$F$400,"TV3*",'M2'!$I$6:$I$400,"<>Cắt / hoãn",'M2'!$I$6:$I$400,"<>Xong",'M2'!$E$6:$E$400,"L4")+SUMIFS('M3'!$G$6:$G$400,'M3'!$F$6:$F$400,"TV3*",'M3'!$I$6:$I$400,"<>Cắt / hoãn",'M3'!$I$6:$I$400,"<>Xong",'M3'!$E$6:$E$400,"L4")+SUMIFS('M4'!$G$6:$G$400,'M4'!$F$6:$F$400,"TV3*",'M4'!$I$6:$I$400,"<>Cắt / hoãn",'M4'!$I$6:$I$400,"<>Xong",'M4'!$E$6:$E$400,"L4")+SUMIFS('M5'!$G$6:$G$400,'M5'!$F$6:$F$400,"TV3*",'M5'!$I$6:$I$400,"<>Cắt / hoãn",'M5'!$I$6:$I$400,"<>Xong",'M5'!$E$6:$E$400,"L4")+SUMIFS('M6'!$G$6:$G$400,'M6'!$F$6:$F$400,"TV3*",'M6'!$I$6:$I$400,"<>Cắt / hoãn",'M6'!$I$6:$I$400,"<>Xong",'M6'!$E$6:$E$400,"L4") -> 0 | E16: =SUM(B16:D16) -> 35
A17: L5 | B17: =SUMIFS('M2'!$G$6:$G$400,'M2'!$F$6:$F$400,"TV1*",'M2'!$I$6:$I$400,"<>Cắt / hoãn",'M2'!$I$6:$I$400,"<>Xong",'M2'!$E$6:$E$400,"L5")+SUMIFS('M3'!$G$6:$G$400,'M3'!$F$6:$F$400,"TV1*",'M3'!$I$6:$I$400,"<>Cắt / hoãn",'M3'!$I$6:$I$400,"<>Xong",'M3'!$E$6:$E$400,"L5")+SUMIFS('M4'!$G$6:$G$400,'M4'!$F$6:$F$400,"TV1*",'M4'!$I$6:$I$400,"<>Cắt / hoãn",'M4'!$I$6:$I$400,"<>Xong",'M4'!$E$6:$E$400,"L5")+SUMIFS('M5'!$G$6:$G$400,'M5'!$F$6:$F$400,"TV1*",'M5'!$I$6:$I$400,"<>Cắt / hoãn",'M5'!$I$6:$I$400,"<>Xong",'M5'!$E$6:$E$400,"L5")+SUMIFS('M6'!$G$6:$G$400,'M6'!$F$6:$F$400,"TV1*",'M6'!$I$6:$I$400,"<>Cắt / hoãn",'M6'!$I$6:$I$400,"<>Xong",'M6'!$E$6:$E$400,"L5") -> 31 | C17: =SUMIFS('M2'!$G$6:$G$400,'M2'!$F$6:$F$400,"TV2*",'M2'!$I$6:$I$400,"<>Cắt / hoãn",'M2'!$I$6:$I$400,"<>Xong",'M2'!$E$6:$E$400,"L5")+SUMIFS('M3'!$G$6:$G$400,'M3'!$F$6:$F$400,"TV2*",'M3'!$I$6:$I$400,"<>Cắt / hoãn",'M3'!$I$6:$I$400,"<>Xong",'M3'!$E$6:$E$400,"L5")+SUMIFS('M4'!$G$6:$G$400,'M4'!$F$6:$F$400,"TV2*",'M4'!$I$6:$I$400,"<>Cắt / hoãn",'M4'!$I$6:$I$400,"<>Xong",'M4'!$E$6:$E$400,"L5")+SUMIFS('M5'!$G$6:$G$400,'M5'!$F$6:$F$400,"TV2*",'M5'!$I$6:$I$400,"<>Cắt / hoãn",'M5'!$I$6:$I$400,"<>Xong",'M5'!$E$6:$E$400,"L5")+SUMIFS('M6'!$G$6:$G$400,'M6'!$F$6:$F$400,"TV2*",'M6'!$I$6:$I$400,"<>Cắt / hoãn",'M6'!$I$6:$I$400,"<>Xong",'M6'!$E$6:$E$400,"L5") -> 0 | D17: =SUMIFS('M2'!$G$6:$G$400,'M2'!$F$6:$F$400,"TV3*",'M2'!$I$6:$I$400,"<>Cắt / hoãn",'M2'!$I$6:$I$400,"<>Xong",'M2'!$E$6:$E$400,"L5")+SUMIFS('M3'!$G$6:$G$400,'M3'!$F$6:$F$400,"TV3*",'M3'!$I$6:$I$400,"<>Cắt / hoãn",'M3'!$I$6:$I$400,"<>Xong",'M3'!$E$6:$E$400,"L5")+SUMIFS('M4'!$G$6:$G$400,'M4'!$F$6:$F$400,"TV3*",'M4'!$I$6:$I$400,"<>Cắt / hoãn",'M4'!$I$6:$I$400,"<>Xong",'M4'!$E$6:$E$400,"L5")+SUMIFS('M5'!$G$6:$G$400,'M5'!$F$6:$F$400,"TV3*",'M5'!$I$6:$I$400,"<>Cắt / hoãn",'M5'!$I$6:$I$400,"<>Xong",'M5'!$E$6:$E$400,"L5")+SUMIFS('M6'!$G$6:$G$400,'M6'!$F$6:$F$400,"TV3*",'M6'!$I$6:$I$400,"<>Cắt / hoãn",'M6'!$I$6:$I$400,"<>Xong",'M6'!$E$6:$E$400,"L5") -> 0 | E17: =SUM(B17:D17) -> 31
A18: L6 | B18: =SUMIFS('M2'!$G$6:$G$400,'M2'!$F$6:$F$400,"TV1*",'M2'!$I$6:$I$400,"<>Cắt / hoãn",'M2'!$I$6:$I$400,"<>Xong",'M2'!$E$6:$E$400,"L6")+SUMIFS('M3'!$G$6:$G$400,'M3'!$F$6:$F$400,"TV1*",'M3'!$I$6:$I$400,"<>Cắt / hoãn",'M3'!$I$6:$I$400,"<>Xong",'M3'!$E$6:$E$400,"L6")+SUMIFS('M4'!$G$6:$G$400,'M4'!$F$6:$F$400,"TV1*",'M4'!$I$6:$I$400,"<>Cắt / hoãn",'M4'!$I$6:$I$400,"<>Xong",'M4'!$E$6:$E$400,"L6")+SUMIFS('M5'!$G$6:$G$400,'M5'!$F$6:$F$400,"TV1*",'M5'!$I$6:$I$400,"<>Cắt / hoãn",'M5'!$I$6:$I$400,"<>Xong",'M5'!$E$6:$E$400,"L6")+SUMIFS('M6'!$G$6:$G$400,'M6'!$F$6:$F$400,"TV1*",'M6'!$I$6:$I$400,"<>Cắt / hoãn",'M6'!$I$6:$I$400,"<>Xong",'M6'!$E$6:$E$400,"L6") -> 21 | C18: =SUMIFS('M2'!$G$6:$G$400,'M2'!$F$6:$F$400,"TV2*",'M2'!$I$6:$I$400,"<>Cắt / hoãn",'M2'!$I$6:$I$400,"<>Xong",'M2'!$E$6:$E$400,"L6")+SUMIFS('M3'!$G$6:$G$400,'M3'!$F$6:$F$400,"TV2*",'M3'!$I$6:$I$400,"<>Cắt / hoãn",'M3'!$I$6:$I$400,"<>Xong",'M3'!$E$6:$E$400,"L6")+SUMIFS('M4'!$G$6:$G$400,'M4'!$F$6:$F$400,"TV2*",'M4'!$I$6:$I$400,"<>Cắt / hoãn",'M4'!$I$6:$I$400,"<>Xong",'M4'!$E$6:$E$400,"L6")+SUMIFS('M5'!$G$6:$G$400,'M5'!$F$6:$F$400,"TV2*",'M5'!$I$6:$I$400,"<>Cắt / hoãn",'M5'!$I$6:$I$400,"<>Xong",'M5'!$E$6:$E$400,"L6")+SUMIFS('M6'!$G$6:$G$400,'M6'!$F$6:$F$400,"TV2*",'M6'!$I$6:$I$400,"<>Cắt / hoãn",'M6'!$I$6:$I$400,"<>Xong",'M6'!$E$6:$E$400,"L6") -> 0 | D18: =SUMIFS('M2'!$G$6:$G$400,'M2'!$F$6:$F$400,"TV3*",'M2'!$I$6:$I$400,"<>Cắt / hoãn",'M2'!$I$6:$I$400,"<>Xong",'M2'!$E$6:$E$400,"L6")+SUMIFS('M3'!$G$6:$G$400,'M3'!$F$6:$F$400,"TV3*",'M3'!$I$6:$I$400,"<>Cắt / hoãn",'M3'!$I$6:$I$400,"<>Xong",'M3'!$E$6:$E$400,"L6")+SUMIFS('M4'!$G$6:$G$400,'M4'!$F$6:$F$400,"TV3*",'M4'!$I$6:$I$400,"<>Cắt / hoãn",'M4'!$I$6:$I$400,"<>Xong",'M4'!$E$6:$E$400,"L6")+SUMIFS('M5'!$G$6:$G$400,'M5'!$F$6:$F$400,"TV3*",'M5'!$I$6:$I$400,"<>Cắt / hoãn",'M5'!$I$6:$I$400,"<>Xong",'M5'!$E$6:$E$400,"L6")+SUMIFS('M6'!$G$6:$G$400,'M6'!$F$6:$F$400,"TV3*",'M6'!$I$6:$I$400,"<>Cắt / hoãn",'M6'!$I$6:$I$400,"<>Xong",'M6'!$E$6:$E$400,"L6") -> 0 | E18: =SUM(B18:D18) -> 21
A19: L7 | B19: =SUMIFS('M2'!$G$6:$G$400,'M2'!$F$6:$F$400,"TV1*",'M2'!$I$6:$I$400,"<>Cắt / hoãn",'M2'!$I$6:$I$400,"<>Xong",'M2'!$E$6:$E$400,"L7")+SUMIFS('M3'!$G$6:$G$400,'M3'!$F$6:$F$400,"TV1*",'M3'!$I$6:$I$400,"<>Cắt / hoãn",'M3'!$I$6:$I$400,"<>Xong",'M3'!$E$6:$E$400,"L7")+SUMIFS('M4'!$G$6:$G$400,'M4'!$F$6:$F$400,"TV1*",'M4'!$I$6:$I$400,"<>Cắt / hoãn",'M4'!$I$6:$I$400,"<>Xong",'M4'!$E$6:$E$400,"L7")+SUMIFS('M5'!$G$6:$G$400,'M5'!$F$6:$F$400,"TV1*",'M5'!$I$6:$I$400,"<>Cắt / hoãn",'M5'!$I$6:$I$400,"<>Xong",'M5'!$E$6:$E$400,"L7")+SUMIFS('M6'!$G$6:$G$400,'M6'!$F$6:$F$400,"TV1*",'M6'!$I$6:$I$400,"<>Cắt / hoãn",'M6'!$I$6:$I$400,"<>Xong",'M6'!$E$6:$E$400,"L7") -> 8 | C19: =SUMIFS('M2'!$G$6:$G$400,'M2'!$F$6:$F$400,"TV2*",'M2'!$I$6:$I$400,"<>Cắt / hoãn",'M2'!$I$6:$I$400,"<>Xong",'M2'!$E$6:$E$400,"L7")+SUMIFS('M3'!$G$6:$G$400,'M3'!$F$6:$F$400,"TV2*",'M3'!$I$6:$I$400,"<>Cắt / hoãn",'M3'!$I$6:$I$400,"<>Xong",'M3'!$E$6:$E$400,"L7")+SUMIFS('M4'!$G$6:$G$400,'M4'!$F$6:$F$400,"TV2*",'M4'!$I$6:$I$400,"<>Cắt / hoãn",'M4'!$I$6:$I$400,"<>Xong",'M4'!$E$6:$E$400,"L7")+SUMIFS('M5'!$G$6:$G$400,'M5'!$F$6:$F$400,"TV2*",'M5'!$I$6:$I$400,"<>Cắt / hoãn",'M5'!$I$6:$I$400,"<>Xong",'M5'!$E$6:$E$400,"L7")+SUMIFS('M6'!$G$6:$G$400,'M6'!$F$6:$F$400,"TV2*",'M6'!$I$6:$I$400,"<>Cắt / hoãn",'M6'!$I$6:$I$400,"<>Xong",'M6'!$E$6:$E$400,"L7") -> 0 | D19: =SUMIFS('M2'!$G$6:$G$400,'M2'!$F$6:$F$400,"TV3*",'M2'!$I$6:$I$400,"<>Cắt / hoãn",'M2'!$I$6:$I$400,"<>Xong",'M2'!$E$6:$E$400,"L7")+SUMIFS('M3'!$G$6:$G$400,'M3'!$F$6:$F$400,"TV3*",'M3'!$I$6:$I$400,"<>Cắt / hoãn",'M3'!$I$6:$I$400,"<>Xong",'M3'!$E$6:$E$400,"L7")+SUMIFS('M4'!$G$6:$G$400,'M4'!$F$6:$F$400,"TV3*",'M4'!$I$6:$I$400,"<>Cắt / hoãn",'M4'!$I$6:$I$400,"<>Xong",'M4'!$E$6:$E$400,"L7")+SUMIFS('M5'!$G$6:$G$400,'M5'!$F$6:$F$400,"TV3*",'M5'!$I$6:$I$400,"<>Cắt / hoãn",'M5'!$I$6:$I$400,"<>Xong",'M5'!$E$6:$E$400,"L7")+SUMIFS('M6'!$G$6:$G$400,'M6'!$F$6:$F$400,"TV3*",'M6'!$I$6:$I$400,"<>Cắt / hoãn",'M6'!$I$6:$I$400,"<>Xong",'M6'!$E$6:$E$400,"L7") -> 26 | E19: =SUM(B19:D19) -> 34
A20: L8 | B20: =SUMIFS('M2'!$G$6:$G$400,'M2'!$F$6:$F$400,"TV1*",'M2'!$I$6:$I$400,"<>Cắt / hoãn",'M2'!$I$6:$I$400,"<>Xong",'M2'!$E$6:$E$400,"L8")+SUMIFS('M3'!$G$6:$G$400,'M3'!$F$6:$F$400,"TV1*",'M3'!$I$6:$I$400,"<>Cắt / hoãn",'M3'!$I$6:$I$400,"<>Xong",'M3'!$E$6:$E$400,"L8")+SUMIFS('M4'!$G$6:$G$400,'M4'!$F$6:$F$400,"TV1*",'M4'!$I$6:$I$400,"<>Cắt / hoãn",'M4'!$I$6:$I$400,"<>Xong",'M4'!$E$6:$E$400,"L8")+SUMIFS('M5'!$G$6:$G$400,'M5'!$F$6:$F$400,"TV1*",'M5'!$I$6:$I$400,"<>Cắt / hoãn",'M5'!$I$6:$I$400,"<>Xong",'M5'!$E$6:$E$400,"L8")+SUMIFS('M6'!$G$6:$G$400,'M6'!$F$6:$F$400,"TV1*",'M6'!$I$6:$I$400,"<>Cắt / hoãn",'M6'!$I$6:$I$400,"<>Xong",'M6'!$E$6:$E$400,"L8") -> 2 | C20: =SUMIFS('M2'!$G$6:$G$400,'M2'!$F$6:$F$400,"TV2*",'M2'!$I$6:$I$400,"<>Cắt / hoãn",'M2'!$I$6:$I$400,"<>Xong",'M2'!$E$6:$E$400,"L8")+SUMIFS('M3'!$G$6:$G$400,'M3'!$F$6:$F$400,"TV2*",'M3'!$I$6:$I$400,"<>Cắt / hoãn",'M3'!$I$6:$I$400,"<>Xong",'M3'!$E$6:$E$400,"L8")+SUMIFS('M4'!$G$6:$G$400,'M4'!$F$6:$F$400,"TV2*",'M4'!$I$6:$I$400,"<>Cắt / hoãn",'M4'!$I$6:$I$400,"<>Xong",'M4'!$E$6:$E$400,"L8")+SUMIFS('M5'!$G$6:$G$400,'M5'!$F$6:$F$400,"TV2*",'M5'!$I$6:$I$400,"<>Cắt / hoãn",'M5'!$I$6:$I$400,"<>Xong",'M5'!$E$6:$E$400,"L8")+SUMIFS('M6'!$G$6:$G$400,'M6'!$F$6:$F$400,"TV2*",'M6'!$I$6:$I$400,"<>Cắt / hoãn",'M6'!$I$6:$I$400,"<>Xong",'M6'!$E$6:$E$400,"L8") -> 2 | D20: =SUMIFS('M2'!$G$6:$G$400,'M2'!$F$6:$F$400,"TV3*",'M2'!$I$6:$I$400,"<>Cắt / hoãn",'M2'!$I$6:$I$400,"<>Xong",'M2'!$E$6:$E$400,"L8")+SUMIFS('M3'!$G$6:$G$400,'M3'!$F$6:$F$400,"TV3*",'M3'!$I$6:$I$400,"<>Cắt / hoãn",'M3'!$I$6:$I$400,"<>Xong",'M3'!$E$6:$E$400,"L8")+SUMIFS('M4'!$G$6:$G$400,'M4'!$F$6:$F$400,"TV3*",'M4'!$I$6:$I$400,"<>Cắt / hoãn",'M4'!$I$6:$I$400,"<>Xong",'M4'!$E$6:$E$400,"L8")+SUMIFS('M5'!$G$6:$G$400,'M5'!$F$6:$F$400,"TV3*",'M5'!$I$6:$I$400,"<>Cắt / hoãn",'M5'!$I$6:$I$400,"<>Xong",'M5'!$E$6:$E$400,"L8")+SUMIFS('M6'!$G$6:$G$400,'M6'!$F$6:$F$400,"TV3*",'M6'!$I$6:$I$400,"<>Cắt / hoãn",'M6'!$I$6:$I$400,"<>Xong",'M6'!$E$6:$E$400,"L8") -> 23 | E20: =SUM(B20:D20) -> 27
A21: L9 | B21: =SUMIFS('M2'!$G$6:$G$400,'M2'!$F$6:$F$400,"TV1*",'M2'!$I$6:$I$400,"<>Cắt / hoãn",'M2'!$I$6:$I$400,"<>Xong",'M2'!$E$6:$E$400,"L9")+SUMIFS('M3'!$G$6:$G$400,'M3'!$F$6:$F$400,"TV1*",'M3'!$I$6:$I$400,"<>Cắt / hoãn",'M3'!$I$6:$I$400,"<>Xong",'M3'!$E$6:$E$400,"L9")+SUMIFS('M4'!$G$6:$G$400,'M4'!$F$6:$F$400,"TV1*",'M4'!$I$6:$I$400,"<>Cắt / hoãn",'M4'!$I$6:$I$400,"<>Xong",'M4'!$E$6:$E$400,"L9")+SUMIFS('M5'!$G$6:$G$400,'M5'!$F$6:$F$400,"TV1*",'M5'!$I$6:$I$400,"<>Cắt / hoãn",'M5'!$I$6:$I$400,"<>Xong",'M5'!$E$6:$E$400,"L9")+SUMIFS('M6'!$G$6:$G$400,'M6'!$F$6:$F$400,"TV1*",'M6'!$I$6:$I$400,"<>Cắt / hoãn",'M6'!$I$6:$I$400,"<>Xong",'M6'!$E$6:$E$400,"L9") -> 10 | C21: =SUMIFS('M2'!$G$6:$G$400,'M2'!$F$6:$F$400,"TV2*",'M2'!$I$6:$I$400,"<>Cắt / hoãn",'M2'!$I$6:$I$400,"<>Xong",'M2'!$E$6:$E$400,"L9")+SUMIFS('M3'!$G$6:$G$400,'M3'!$F$6:$F$400,"TV2*",'M3'!$I$6:$I$400,"<>Cắt / hoãn",'M3'!$I$6:$I$400,"<>Xong",'M3'!$E$6:$E$400,"L9")+SUMIFS('M4'!$G$6:$G$400,'M4'!$F$6:$F$400,"TV2*",'M4'!$I$6:$I$400,"<>Cắt / hoãn",'M4'!$I$6:$I$400,"<>Xong",'M4'!$E$6:$E$400,"L9")+SUMIFS('M5'!$G$6:$G$400,'M5'!$F$6:$F$400,"TV2*",'M5'!$I$6:$I$400,"<>Cắt / hoãn",'M5'!$I$6:$I$400,"<>Xong",'M5'!$E$6:$E$400,"L9")+SUMIFS('M6'!$G$6:$G$400,'M6'!$F$6:$F$400,"TV2*",'M6'!$I$6:$I$400,"<>Cắt / hoãn",'M6'!$I$6:$I$400,"<>Xong",'M6'!$E$6:$E$400,"L9") -> 13 | D21: =SUMIFS('M2'!$G$6:$G$400,'M2'!$F$6:$F$400,"TV3*",'M2'!$I$6:$I$400,"<>Cắt / hoãn",'M2'!$I$6:$I$400,"<>Xong",'M2'!$E$6:$E$400,"L9")+SUMIFS('M3'!$G$6:$G$400,'M3'!$F$6:$F$400,"TV3*",'M3'!$I$6:$I$400,"<>Cắt / hoãn",'M3'!$I$6:$I$400,"<>Xong",'M3'!$E$6:$E$400,"L9")+SUMIFS('M4'!$G$6:$G$400,'M4'!$F$6:$F$400,"TV3*",'M4'!$I$6:$I$400,"<>Cắt / hoãn",'M4'!$I$6:$I$400,"<>Xong",'M4'!$E$6:$E$400,"L9")+SUMIFS('M5'!$G$6:$G$400,'M5'!$F$6:$F$400,"TV3*",'M5'!$I$6:$I$400,"<>Cắt / hoãn",'M5'!$I$6:$I$400,"<>Xong",'M5'!$E$6:$E$400,"L9")+SUMIFS('M6'!$G$6:$G$400,'M6'!$F$6:$F$400,"TV3*",'M6'!$I$6:$I$400,"<>Cắt / hoãn",'M6'!$I$6:$I$400,"<>Xong",'M6'!$E$6:$E$400,"L9") -> 5 | E21: =SUM(B21:D21) -> 28
A22: L10 | B22: =SUMIFS('M2'!$G$6:$G$400,'M2'!$F$6:$F$400,"TV1*",'M2'!$I$6:$I$400,"<>Cắt / hoãn",'M2'!$I$6:$I$400,"<>Xong",'M2'!$E$6:$E$400,"L10")+SUMIFS('M3'!$G$6:$G$400,'M3'!$F$6:$F$400,"TV1*",'M3'!$I$6:$I$400,"<>Cắt / hoãn",'M3'!$I$6:$I$400,"<>Xong",'M3'!$E$6:$E$400,"L10")+SUMIFS('M4'!$G$6:$G$400,'M4'!$F$6:$F$400,"TV1*",'M4'!$I$6:$I$400,"<>Cắt / hoãn",'M4'!$I$6:$I$400,"<>Xong",'M4'!$E$6:$E$400,"L10")+SUMIFS('M5'!$G$6:$G$400,'M5'!$F$6:$F$400,"TV1*",'M5'!$I$6:$I$400,"<>Cắt / hoãn",'M5'!$I$6:$I$400,"<>Xong",'M5'!$E$6:$E$400,"L10")+SUMIFS('M6'!$G$6:$G$400,'M6'!$F$6:$F$400,"TV1*",'M6'!$I$6:$I$400,"<>Cắt / hoãn",'M6'!$I$6:$I$400,"<>Xong",'M6'!$E$6:$E$400,"L10") -> 18 | C22: =SUMIFS('M2'!$G$6:$G$400,'M2'!$F$6:$F$400,"TV2*",'M2'!$I$6:$I$400,"<>Cắt / hoãn",'M2'!$I$6:$I$400,"<>Xong",'M2'!$E$6:$E$400,"L10")+SUMIFS('M3'!$G$6:$G$400,'M3'!$F$6:$F$400,"TV2*",'M3'!$I$6:$I$400,"<>Cắt / hoãn",'M3'!$I$6:$I$400,"<>Xong",'M3'!$E$6:$E$400,"L10")+SUMIFS('M4'!$G$6:$G$400,'M4'!$F$6:$F$400,"TV2*",'M4'!$I$6:$I$400,"<>Cắt / hoãn",'M4'!$I$6:$I$400,"<>Xong",'M4'!$E$6:$E$400,"L10")+SUMIFS('M5'!$G$6:$G$400,'M5'!$F$6:$F$400,"TV2*",'M5'!$I$6:$I$400,"<>Cắt / hoãn",'M5'!$I$6:$I$400,"<>Xong",'M5'!$E$6:$E$400,"L10")+SUMIFS('M6'!$G$6:$G$400,'M6'!$F$6:$F$400,"TV2*",'M6'!$I$6:$I$400,"<>Cắt / hoãn",'M6'!$I$6:$I$400,"<>Xong",'M6'!$E$6:$E$400,"L10") -> 2 | D22: =SUMIFS('M2'!$G$6:$G$400,'M2'!$F$6:$F$400,"TV3*",'M2'!$I$6:$I$400,"<>Cắt / hoãn",'M2'!$I$6:$I$400,"<>Xong",'M2'!$E$6:$E$400,"L10")+SUMIFS('M3'!$G$6:$G$400,'M3'!$F$6:$F$400,"TV3*",'M3'!$I$6:$I$400,"<>Cắt / hoãn",'M3'!$I$6:$I$400,"<>Xong",'M3'!$E$6:$E$400,"L10")+SUMIFS('M4'!$G$6:$G$400,'M4'!$F$6:$F$400,"TV3*",'M4'!$I$6:$I$400,"<>Cắt / hoãn",'M4'!$I$6:$I$400,"<>Xong",'M4'!$E$6:$E$400,"L10")+SUMIFS('M5'!$G$6:$G$400,'M5'!$F$6:$F$400,"TV3*",'M5'!$I$6:$I$400,"<>Cắt / hoãn",'M5'!$I$6:$I$400,"<>Xong",'M5'!$E$6:$E$400,"L10")+SUMIFS('M6'!$G$6:$G$400,'M6'!$F$6:$F$400,"TV3*",'M6'!$I$6:$I$400,"<>Cắt / hoãn",'M6'!$I$6:$I$400,"<>Xong",'M6'!$E$6:$E$400,"L10") -> 3 | E22: =SUM(B22:D22) -> 23
A23: L11 | B23: =SUMIFS('M2'!$G$6:$G$400,'M2'!$F$6:$F$400,"TV1*",'M2'!$I$6:$I$400,"<>Cắt / hoãn",'M2'!$I$6:$I$400,"<>Xong",'M2'!$E$6:$E$400,"L11")+SUMIFS('M3'!$G$6:$G$400,'M3'!$F$6:$F$400,"TV1*",'M3'!$I$6:$I$400,"<>Cắt / hoãn",'M3'!$I$6:$I$400,"<>Xong",'M3'!$E$6:$E$400,"L11")+SUMIFS('M4'!$G$6:$G$400,'M4'!$F$6:$F$400,"TV1*",'M4'!$I$6:$I$400,"<>Cắt / hoãn",'M4'!$I$6:$I$400,"<>Xong",'M4'!$E$6:$E$400,"L11")+SUMIFS('M5'!$G$6:$G$400,'M5'!$F$6:$F$400,"TV1*",'M5'!$I$6:$I$400,"<>Cắt / hoãn",'M5'!$I$6:$I$400,"<>Xong",'M5'!$E$6:$E$400,"L11")+SUMIFS('M6'!$G$6:$G$400,'M6'!$F$6:$F$400,"TV1*",'M6'!$I$6:$I$400,"<>Cắt / hoãn",'M6'!$I$6:$I$400,"<>Xong",'M6'!$E$6:$E$400,"L11") -> 4 | C23: =SUMIFS('M2'!$G$6:$G$400,'M2'!$F$6:$F$400,"TV2*",'M2'!$I$6:$I$400,"<>Cắt / hoãn",'M2'!$I$6:$I$400,"<>Xong",'M2'!$E$6:$E$400,"L11")+SUMIFS('M3'!$G$6:$G$400,'M3'!$F$6:$F$400,"TV2*",'M3'!$I$6:$I$400,"<>Cắt / hoãn",'M3'!$I$6:$I$400,"<>Xong",'M3'!$E$6:$E$400,"L11")+SUMIFS('M4'!$G$6:$G$400,'M4'!$F$6:$F$400,"TV2*",'M4'!$I$6:$I$400,"<>Cắt / hoãn",'M4'!$I$6:$I$400,"<>Xong",'M4'!$E$6:$E$400,"L11")+SUMIFS('M5'!$G$6:$G$400,'M5'!$F$6:$F$400,"TV2*",'M5'!$I$6:$I$400,"<>Cắt / hoãn",'M5'!$I$6:$I$400,"<>Xong",'M5'!$E$6:$E$400,"L11")+SUMIFS('M6'!$G$6:$G$400,'M6'!$F$6:$F$400,"TV2*",'M6'!$I$6:$I$400,"<>Cắt / hoãn",'M6'!$I$6:$I$400,"<>Xong",'M6'!$E$6:$E$400,"L11") -> 5 | D23: =SUMIFS('M2'!$G$6:$G$400,'M2'!$F$6:$F$400,"TV3*",'M2'!$I$6:$I$400,"<>Cắt / hoãn",'M2'!$I$6:$I$400,"<>Xong",'M2'!$E$6:$E$400,"L11")+SUMIFS('M3'!$G$6:$G$400,'M3'!$F$6:$F$400,"TV3*",'M3'!$I$6:$I$400,"<>Cắt / hoãn",'M3'!$I$6:$I$400,"<>Xong",'M3'!$E$6:$E$400,"L11")+SUMIFS('M4'!$G$6:$G$400,'M4'!$F$6:$F$400,"TV3*",'M4'!$I$6:$I$400,"<>Cắt / hoãn",'M4'!$I$6:$I$400,"<>Xong",'M4'!$E$6:$E$400,"L11")+SUMIFS('M5'!$G$6:$G$400,'M5'!$F$6:$F$400,"TV3*",'M5'!$I$6:$I$400,"<>Cắt / hoãn",'M5'!$I$6:$I$400,"<>Xong",'M5'!$E$6:$E$400,"L11")+SUMIFS('M6'!$G$6:$G$400,'M6'!$F$6:$F$400,"TV3*",'M6'!$I$6:$I$400,"<>Cắt / hoãn",'M6'!$I$6:$I$400,"<>Xong",'M6'!$E$6:$E$400,"L11") -> 3 | E23: =SUM(B23:D23) -> 12
A24: L12 | B24: =SUMIFS('M2'!$G$6:$G$400,'M2'!$F$6:$F$400,"TV1*",'M2'!$I$6:$I$400,"<>Cắt / hoãn",'M2'!$I$6:$I$400,"<>Xong",'M2'!$E$6:$E$400,"L12")+SUMIFS('M3'!$G$6:$G$400,'M3'!$F$6:$F$400,"TV1*",'M3'!$I$6:$I$400,"<>Cắt / hoãn",'M3'!$I$6:$I$400,"<>Xong",'M3'!$E$6:$E$400,"L12")+SUMIFS('M4'!$G$6:$G$400,'M4'!$F$6:$F$400,"TV1*",'M4'!$I$6:$I$400,"<>Cắt / hoãn",'M4'!$I$6:$I$400,"<>Xong",'M4'!$E$6:$E$400,"L12")+SUMIFS('M5'!$G$6:$G$400,'M5'!$F$6:$F$400,"TV1*",'M5'!$I$6:$I$400,"<>Cắt / hoãn",'M5'!$I$6:$I$400,"<>Xong",'M5'!$E$6:$E$400,"L12")+SUMIFS('M6'!$G$6:$G$400,'M6'!$F$6:$F$400,"TV1*",'M6'!$I$6:$I$400,"<>Cắt / hoãn",'M6'!$I$6:$I$400,"<>Xong",'M6'!$E$6:$E$400,"L12") -> 0 | C24: =SUMIFS('M2'!$G$6:$G$400,'M2'!$F$6:$F$400,"TV2*",'M2'!$I$6:$I$400,"<>Cắt / hoãn",'M2'!$I$6:$I$400,"<>Xong",'M2'!$E$6:$E$400,"L12")+SUMIFS('M3'!$G$6:$G$400,'M3'!$F$6:$F$400,"TV2*",'M3'!$I$6:$I$400,"<>Cắt / hoãn",'M3'!$I$6:$I$400,"<>Xong",'M3'!$E$6:$E$400,"L12")+SUMIFS('M4'!$G$6:$G$400,'M4'!$F$6:$F$400,"TV2*",'M4'!$I$6:$I$400,"<>Cắt / hoãn",'M4'!$I$6:$I$400,"<>Xong",'M4'!$E$6:$E$400,"L12")+SUMIFS('M5'!$G$6:$G$400,'M5'!$F$6:$F$400,"TV2*",'M5'!$I$6:$I$400,"<>Cắt / hoãn",'M5'!$I$6:$I$400,"<>Xong",'M5'!$E$6:$E$400,"L12")+SUMIFS('M6'!$G$6:$G$400,'M6'!$F$6:$F$400,"TV2*",'M6'!$I$6:$I$400,"<>Cắt / hoãn",'M6'!$I$6:$I$400,"<>Xong",'M6'!$E$6:$E$400,"L12") -> 5 | D24: =SUMIFS('M2'!$G$6:$G$400,'M2'!$F$6:$F$400,"TV3*",'M2'!$I$6:$I$400,"<>Cắt / hoãn",'M2'!$I$6:$I$400,"<>Xong",'M2'!$E$6:$E$400,"L12")+SUMIFS('M3'!$G$6:$G$400,'M3'!$F$6:$F$400,"TV3*",'M3'!$I$6:$I$400,"<>Cắt / hoãn",'M3'!$I$6:$I$400,"<>Xong",'M3'!$E$6:$E$400,"L12")+SUMIFS('M4'!$G$6:$G$400,'M4'!$F$6:$F$400,"TV3*",'M4'!$I$6:$I$400,"<>Cắt / hoãn",'M4'!$I$6:$I$400,"<>Xong",'M4'!$E$6:$E$400,"L12")+SUMIFS('M5'!$G$6:$G$400,'M5'!$F$6:$F$400,"TV3*",'M5'!$I$6:$I$400,"<>Cắt / hoãn",'M5'!$I$6:$I$400,"<>Xong",'M5'!$E$6:$E$400,"L12")+SUMIFS('M6'!$G$6:$G$400,'M6'!$F$6:$F$400,"TV3*",'M6'!$I$6:$I$400,"<>Cắt / hoãn",'M6'!$I$6:$I$400,"<>Xong",'M6'!$E$6:$E$400,"L12") -> 0 | E24: =SUM(B24:D24) -> 5

Sheet M0
A1: M0 · Setup hạ tầng — chốt 18/09/2026 · Sprint L0
A2: Mục tiêu: L0 — 07/09 – 18/09/2026: Monorepo, Docker Compose, NestJS, Next.js, CI, khung i18n
A3: Nếu trượt: M0 trượt tối đa 3 ngày làm việc. Quá 3 ngày thì rút E1-S8 xuống mức script và đẩy phần còn lại vào S1 — không được để trượt lan sang M1 vì M1 nằm trên đường găng. Tinh gọn: Phương án script cho E1-S8 (còn 4 SP) đã được dùng sẵn, nên M0 không còn đòn bẩy hạ tải nào khác. Mọi phần trượt ăn thẳng vào L1, vốn đã xếp 32 SP story còn mở trên sức chứa 28.
A4: Tiến độ | C4: =COUNTA($C$6:$C$400)&" mục" -> 35 mục | D4: ="Xong: "&COUNTIF($I$6:$I$400,"Xong") -> Xong: 9 | E4: ="Một phần: "&COUNTIF($I$6:$I$400,"Một phần") -> Một phần: 5 | F4: ="Chưa làm: "&COUNTIF($I$6:$I$400,"Chưa làm") -> Chưa làm: 10 | G4: ="Bị chặn: "&COUNTIF($I$6:$I$400,"Bị chặn") -> Bị chặn: 0 | H4: ="Cần chốt: "&COUNTIF($I$6:$I$400,"Cần chốt") -> Cần chốt: 1 | I4: ="Chưa xác nhận: "&COUNTIF($I$6:$I$400,"Chưa xác nhận") -> Chưa xác nhận: 5 | J4: ="Cắt / hoãn: "&COUNTIF($I$6:$I$400,"Cắt / hoãn") -> Cắt / hoãn: 5 | K4: ="Tỷ lệ xong: "&TEXT(IFERROR(COUNTIF($I$6:$I$400,"Xong")/(COUNTA($C$6:$C$400)-COUNTIF($I$6:$I$400,"Cắt / hoãn")),0),"0%") -> Tỷ lệ xong: 30%
A5: STT | B5: Nhóm | C5: Mã | D5: Nội dung | E5: Sprint | F5: Phụ trách | G5: SP | H5: Ưu tiên | I5: Trạng thái | J5: Ghi chú / bằng chứng | K5: Nguồn | L5: Người xác nhận | M5: Ngày xong
A6: 1 | B6: Việc chặn & cần chốt | C6: CH-06 | D6: Chốt quy mô đội: đủ đội 5,5 FTE hay tinh gọn 2 dev + Founder. Git log hiện chỉ có 1 người commit; velocity 53 SP/sprint của S1 dựa trên đội đủ. | F6: Founder | I6: Xong | J6: Chốt 19/09/2026: tinh gọn 2 dev + Founder, cắt nhóm A + B, M6 dời sang 01/04/2027 (QĐ-77). Founder còn phải ký bảng "Những gì mất đi khi cắt" (doc 08 §10.5). Cập nhật 23/09/2026 (QĐ-78): đội code là 3 thành viên chia khối lượng 60-20-20 theo chức năng (TV1 dùng AI, TV2, TV3); Founder giữ việc không code; phạm vi cắt nhóm A + B và lịch L0 → L12 giữ nguyên. | K6: Doc 00 §9 · Kiểm tra code 18/09/2026 · QĐ-77
A7: 2 | B7: Việc chặn & cần chốt | C7: T-TL-01 | D7: Tạo ops/legal/ + ops/legal/drafts/ cho bản nháp ToS / Privacy. | E7: L0 | F7: TV1 | I7: Xong | J7: Xong 19/09/2026: ops/legal/ có README (quy tắc, cấu trúc, việc cấm commit), .gitignore dạng danh sách cho phép, drafts/, registers/, map-audit/. Repo đang public nên chưa tạo counsel/, filings/, procedures/, chờ Founder chốt (ops/legal/README.md §4). Tinh gọn: Founder soạn bản thảo ToS/Privacy, luật sư rà soát và ký. | K7: Doc 00 §10 · ops/legal/README.md
A8: 3 | B8: Việc chặn & cần chốt | C8: T-TL-02 | D8: Secret scanning (gitleaks) + tách biến môi trường trong CI, trước khi nạp khoá JWT, OAuth, Apple .p8. | F8: TV1 | I8: Chưa làm | J8: Rủi ro tăng ngay trong Sprint 1. Tinh gọn: Không còn khoá Apple .p8 vì E2-S4 bị cắt; thêm khoá riêng VAPID của Web Push (L6) vào danh sách secret | K8: Doc 00 §10 · Kiểm tra code 18/09/2026
A9: 4 | B9: Story | C9: E1-S1 | D9: Monorepo + chuẩn code thống nhất | E9: L0 | F9: TV1 | G9: 5 | H9: MUST | I9: Xong | J9: Monorepo pnpm + Turborepo + oxlint chạy được. | K9: Kiểm tra code 18/09/2026
A10: 5 | B10: Story | C10: E1-S2 | D10: docker compose up = Postgres 16 + PostGIS 3.4 + Redis | E10: L0 | F10: TV1 | G10: 5 | H10: MUST | I10: Xong | J10: PostgreSQL 18 + PostGIS 3.6 + Redis 7.4 (nâng phiên bản đã quyết, khác số ghi trong doc 08). | K10: Kiểm tra code 18/09/2026
A11: 6 | B11: Story | C11: E1-S3 | D11: Khung NestJS 11 + config theo môi trường + GET /health | E11: L0 | F11: TV1 | G11: 5 | H11: MUST | I11: Xong | J11: Có /health; thiếu readiness kiểm tra DB và Redis. Xong 24/09/2026: thêm GET /api/v1/health/ready kiểm PostgreSQL + Redis cache + Redis queue, trả 200 hoặc 503 kèm tên dịch vụ đang hỏng (e2e health.e2e.spec.ts; chạy thật: tắt Redis cache → 503, bật lại → 200). | K11: Kiểm tra code 18/09/2026 | M11: 24/09/2026
A12: 7 | B12: Story | C12: E1-S4 | D12: TypeORM migration + seed data | E12: L0 | F12: TV1 | G12: 5 | H12: MUST | I12: Cần chốt | J12: Không dùng TypeORM: schema là file SQL nạp qua initdb, không tự áp cho DB đang chạy. Chốt cơ chế migration (T-04) trước bảng mới đầu tiên. Tinh gọn: Không nằm trong 28 SP của L0; phải chốt cơ chế migration trước khi TV1 tạo users.role và trust_signals ở L1 | K12: Kiểm tra code 18/09/2026
A13: 8 | B13: Story | C13: E1-S5 | D13: Khung Next.js 15 App Router + Tailwind + design token | E13: L0 | F13: TV1 | G13: 5 | H13: MUST | I13: Xong | J13: Next.js 16 App Router + Tailwind 4 + token từ @dnc/tokens. Tinh gọn: @dnc/tokens chưa khớp doc 10 §12 (primary #0EA5E9, doc 10 dùng teal-500 #0E7C74); Designer thuê ngoài giao design token trong gói 4 tuần (TG-M0-1), TV1 thay vào @dnc/tokens | K13: Kiểm tra code 18/09/2026
A14: 9 | B14: Story | C14: E1-S6 | D14: Khung Expo 54 + RN 0.81 + điều hướng + dev build máy thật | F14: Founder | G14: 8 | H14: MUST | I14: Cắt / hoãn | J14: apps/mobile-client-side chỉ có README. Chặn cứng 18 SP mobile của Sprint 1 (E2-S3, E2-S4, E2-S9). Tinh gọn: Hoãn nhánh native sang sau ra mắt, không có repo mobile trong 7 tháng đầu; thay bằng PWA (manifest, service worker, add-to-home) do TV2 làm (TG-M5-1, TG-M5-2) | K14: Kiểm tra code 18/09/2026 · Doc 08 §10.2
A15: 10 | B15: Story | C15: E1-S7 | D15: CI GitHub Actions: lint + test + build mỗi PR | E15: L0 | F15: TV1 | G15: 5 | H15: MUST | I15: Một phần | J15: CI có lint + typecheck + test + smoke RSVP; thiếu bước build; branch protection chưa xác nhận. | K15: Kiểm tra code 18/09/2026
A16: 11 | B16: Story | C16: E1-S8 | D16: Merge develop → tự động deploy staging | E16: L0 | F16: TV1 | G16: 4 | H16: MUST | I16: Chưa làm | J16: Chưa có auto-deploy staging, cũng chưa có script deploy.sh dự phòng. Tinh gọn: Nhóm B rút gọn 8 → 4 SP: deploy staging bằng một lệnh chạy tay (deploy.sh), bỏ auto-deploy, mỗi lần mất thêm khoảng 2 phút; vẫn đạt gate vì M0-5 chấp nhận script một lệnh | K16: Kiểm tra code 18/09/2026 · Doc 08 §10.2
A17: 12 | B17: Story | C17: E10-S1 | D17: Khoá i18n theo namespace, dùng chung web + mobile | E17: L0 | F17: TV2 | G17: 3 | H17: MUST | I17: Xong | J17: packages/i18n en/vi + sinh kiểu khoá; 2 file phẳng thay vì 14 namespace (vẫn đạt DoD). Tinh gọn: Không có app mobile trong kịch bản tinh gọn: khoá chỉ dùng cho web client + Admin Console; bản dịch VI do dịch giả thuê ngoài, TV2 nạp file ở L11 | K17: Kiểm tra code 18/09/2026
A18: 13 | B18: DoD bổ sung | C18: S0-DoD-1 | D18: Người thứ hai trong đội làm theo README từ máy sạch, dựng xong toàn hệ thống trong ≤ 5 phút bấm đồng hồ, không hỏi ai | E18: L0 | F18: TV1 | I18: Một phần | J18: Lệnh pnpm dev tự động hoá đủ; chưa có lần bấm giờ thật trên máy sạch. Tinh gọn: TV2 hoặc TV3 là người thứ hai bấm giờ trên máy sạch | K18: Doc 08 §6
A19: 14 | B19: DoD bổ sung | C19: S0-DoD-2 | D19: GET /health trả 200 từ tên miền staging thật (không phải IP), có HTTPS hợp lệ | E19: L0 | F19: TV1 | I19: Chưa làm | J19: Chưa có staging (phụ thuộc E1-S8). Tinh gọn: Staging dựng bằng deploy một lệnh (E1-S8 rút gọn); tên miền do Founder đăng ký (S0-Ops-3) | K19: Doc 08 §6
A20: 15 | B20: DoD bổ sung | C20: S0-DoD-3 | D20: CI chạy < 8 phút; PR đỏ không merge được (branch protection đã bật) | E20: L0 | F20: TV1 | I20: Chưa xác nhận | J20: Cần người có quyền admin repo kiểm branch protection và đo thời gian CI thật. Tinh gọn: Không có QA thường trực: branch protection bắt buộc 1 approve từ dev còn lại (review chéo) | K20: Doc 08 §6
A21: 16 | B21: DoD bổ sung | C21: S0-DoD-4 | D21: Dev build cài được lên 1 iPhone thật + 1 Android thật, ảnh chụp màn hình lưu trong issue | F21: Founder | I21: Cắt / hoãn | J21: Chưa có project Expo (E1-S6). Tinh gọn: Không có dev build native (E1-S6 hoãn); việc kiểm tra cài PWA lên máy thật chuyển sang L9 | K21: Doc 08 §6 · Doc 08 §10.2
A22: 17 | B22: DoD bổ sung | C22: S0-DoD-5 | D22: Khung i18n có sẵn 2 locale en/vi, mặc định en; đã có 1 chuỗi mẫu chứng minh cả hai đường | E22: L0 | F22: TV2 | I22: Xong | K22: Doc 08 §6
A23: 18 | B23: DoD bổ sung | C23: S0-DoD-6 | D23: Sổ đăng ký hoạt động xử lý dữ liệu cá nhân đã tạo file rỗng có cấu trúc, chờ điền từ S1 | E23: L0 | F23: Founder + TV1 | I23: Chưa làm | J23: Chưa có file sổ đăng ký, chưa có thư mục ops/legal/. Tinh gọn: Founder soạn cấu trúc sổ theo Luật 91/2025 (luật sư chỉ rà soát ở gói pháp lý rút gọn); TV1 đặt file vào ops/legal/ | K23: Doc 08 §6
A24: 19 | B24: Nghiệm thu | C24: M0-1 | D24: GET /api/v1/health trả 200 từ tên miền staging có HTTPS hợp lệ | F24: TV1 | I24: Chưa làm | J24: Bằng chứng: Ảnh chụp curl -i + chứng chỉ | K24: Doc 08 §7
A25: 20 | B25: Nghiệm thu | C25: M0-2 | D25: CI xanh trên develop, thời gian chạy < 8 phút, branch protection đã bật | F25: TV1 | I25: Một phần | J25: CI chạy trên PR; thiếu build + branch protection chưa xác nhận. Bằng chứng: Link run CI + ảnh cấu hình | K25: Doc 08 §7
A26: 21 | B26: Nghiệm thu | C26: M0-3 | D26: Người thứ hai dựng local từ máy sạch trong ≤ 5 phút | F26: TV1 | I26: Một phần | J26: Chưa bấm giờ thật. Bằng chứng: Video màn hình bấm đồng hồ. Tinh gọn: TV2 hoặc TV3 là người thứ hai quay video bấm giờ | K26: Doc 08 §7
A27: 22 | B27: Nghiệm thu | C27: M0-4 | D27: Dev build cài chạy trên 1 iPhone thật + 1 Android thật | F27: Founder | I27: Cắt / hoãn | J27: Bằng chứng: 2 ảnh chụp màn hình thiết bị. Tinh gọn: Không có app native trong 7 tháng; bằng chứng cài PWA trên máy thật chuyển sang L9 | K27: Doc 08 §7 · Doc 08 §10.2
A28: 23 | B28: Nghiệm thu | C28: M0-5 | D28: Merge develop → staging tự cập nhật ≤ 10 phút (hoặc script 1 lệnh, xem phương án hạ tải §6.3) | F28: TV1 | I28: Chưa làm | J28: Bằng chứng: Log deploy. Tinh gọn: Nghiệm thu theo nhánh script một lệnh (E1-S8 rút gọn); bằng chứng là log chạy script | K28: Doc 08 §7
A29: 24 | B29: Nghiệm thu | C29: M0-6 | D29: 2 locale en/vi hoạt động, mặc định en | F29: TV2 | I29: Xong | J29: Bằng chứng: Ảnh 2 trạng thái | K29: Doc 08 §7
A30: 25 | B30: Nghiệm thu | C30: M0-7 | D30: Hồ sơ D-U-N-S đã nộp, có mã hồ sơ | F30: Founder | I30: Cắt / hoãn | J30: Việc của Founder, chưa có bằng chứng trong repo. Bằng chứng: Email xác nhận. Tinh gọn: D-U-N-S chỉ dùng để mở tài khoản Apple Developer/Google Play cho app native; E12 hoãn và ngân sách tinh gọn bỏ Apple Developer nên không còn là tiêu chí M0 | K30: Doc 08 §7 · Doc 08 §10.2
A31: 26 | B31: Demo | C31: S0-Demo-1 | D31: Mở terminal máy sạch, git clone + docker compose up, gọi curl localhost:3000/api/v1/health → {"status":"ok"} | E31: L0 | F31: TV1 | I31: Một phần | J31: Chạy được trên localhost; staging chưa có. | K31: Doc 08 §6
A32: 27 | B32: Demo | C32: S0-Demo-2 | D32: Mở trình duyệt vào tên miền staging → trang Next.js chào mừng, bấm nút đổi ngôn ngữ EN ↔ VI | E32: L0 | F32: TV2 + TV1 | I32: Chưa làm | J32: Tinh gọn: Staging cập nhật bằng deploy một lệnh của TV1 | K32: Doc 08 §6
A33: 28 | B33: Demo | C33: S0-Demo-3 | D33: Cầm iPhone thật lên, mở app dev build, đi qua 3 màn hình khung | F33: Founder | I33: Cắt / hoãn | J33: Tinh gọn: Không có app native; demo tương đương là mở PWA trên điện thoại ở L9 | K33: Doc 08 §6 · Doc 08 §10.2
A34: 29 | B34: Demo | C34: S0-Demo-4 | D34: Push 1 commit vô hại lên develop ngay trong buổi demo → mọi người xem CI chạy và staging tự cập nhật sau ~6 phút | E34: L0 | F34: TV1 | I34: Chưa làm | J34: Tinh gọn: Không còn auto-deploy: sau khi CI xanh, TV1 chạy lệnh deploy ngay trong buổi demo | K34: Doc 08 §6
A35: 30 | B35: Việc ngoài SP | C35: S0-Ops-1 | D35: Nộp hồ sơ D-U-N-S Number (miễn phí, 5–14 ngày làm việc) — đây là việc chặn dài nhất của cả dự án, làm ngày đầu tiên | E35: L0 | F35: Founder | I35: Chưa xác nhận | J35: Tinh gọn: Không còn chặn lịch vì app native và phát hành cửa hàng đã hoãn; nộp vẫn miễn phí nếu muốn giữ đường cho bản native sau ra mắt | K35: Doc 08 §6
A36: 31 | B36: Việc ngoài SP | C36: S0-Ops-2 | D36: Mở tài khoản Google Play Console (25 USD một lần) — làm ngay vì chính sách closed testing 14 ngày tính từ lúc có tester | E36: L0 | F36: Founder | I36: Chưa xác nhận | J36: Tinh gọn: Chỉ cần cho app native trên Google Play (E12 hoãn); không còn chặn M5/M6, Founder quyết mở sớm hay dời | K36: Doc 08 §6
A37: 32 | B37: Việc ngoài SP | C37: S0-Ops-3 | D37: Đăng ký tên miền + email doanh nghiệp | E37: L0 | F37: Founder | I37: Chưa xác nhận | K37: Doc 08 §6
A38: 33 | B38: Việc ngoài SP | C38: S0-Ops-4 | D38: Chốt danh sách 20 organizer mục tiêu để tiếp cận từ S2 | E38: L0 | F38: Founder | I38: Chưa xác nhận | J38: Tinh gọn: Tiếp cận từ L2 (trùng lịch S2), giữ nguyên theo NT-1 | K38: Doc 08 §6
A39: 34 | B39: Bổ sung kịch bản tinh gọn | C39: TG-M0-1 | D39: Ký gói Designer thuê ngoài trọn gói: design token + 20 màn hình, giao trong 4 tuần (45 triệu VND, GĐ A) | E39: L0 | F39: Founder | H39: MUST | I39: Chưa làm | J39: Bên giao là Thuê ngoài: Designer; việc bàn giao theo dõi ở TG-M2-1 (khoảng 19/10, đầu L3). Doc 00 đặt hạn token trước 21/09 nên phải ký trong hạn trượt M0 (23/09). DEC-TOKENS (M2) phải chốt trước khi gửi brief vì @dnc/tokens đang lệch doc 10 §12 (E1-S5). Đề xuất đổi phần tài sản cửa hàng trong gói sang icon/splash PWA + ảnh OG vì E12 hoãn; TV1 nạp token vào @dnc/tokens | K39: Doc 08 §9.2 · 08:1518 · §11.3 · 08:1789
A40: 35 | B40: Bổ sung kịch bản tinh gọn | C40: TG-M0-2 | D40: Chốt quy trình nghiệm thu tinh gọn: Founder ký DoD-9 (người thứ hai xác nhận), các thành viên code review chéo story của nhau | E40: L0 | F40: Founder + TV1 | H40: MUST | I40: Chưa làm | J40: Không có QA thường trực (08:1526). TV1 bật yêu cầu 1 approve từ một thành viên khác trên develop (S0-DoD-3). Founder ký DoD-9 trên staging cho mọi story L0–L12 và cho từng gate M1–M6. Đây là mục duy nhất của quy trình này, đã gộp các bản lặp ở M1–M5. Chấp nhận tỷ lệ lỗi lọt ra staging cao hơn | K40: Doc 08 §9.2 · 08:1526

Sheet M1
A1: M1 · API nền + Auth — chốt 02/10/2026 · Sprint L1
A2: Mục tiêu: L1 — 21/09 – 02/10/2026: Auth email + Google, refresh rotation, RBAC enum 5 role, trust_signals
A3: Nếu trượt: M1 không được trượt. Đây là mắt xích đường găng cứng nhất phía kỹ thuật — toàn bộ E3, E4, E6 đều chờ nó. Trượt M1 thì trượt hết. Phương án khẩn: cắt E2-S5 (Facebook) và E2-S6 (đặt lại mật khẩu) sang S2, dồn 2 người vào E2-S2 và E2-S9. Tinh gọn: E2-S4 và E2-S5 đã cắt, E2-S9 đã hoãn và E2-S2 đã xong, nên phương án khẩn là dời E1-S9 (Sentry chỉ cần trước khi staging có người dùng thật, tức beta L10) và E2-S6 sang L2, dồn TV2 vào E2-S1 và E2-S3 (Google trên web), TV1 hỗ trợ E2-S1 khi xong phần L0 còn tồn.
A4: Tiến độ | C4: =COUNTA($C$6:$C$400)&" mục" -> 49 mục | D4: ="Xong: "&COUNTIF($I$6:$I$400,"Xong") -> Xong: 11 | E4: ="Một phần: "&COUNTIF($I$6:$I$400,"Một phần") -> Một phần: 7 | F4: ="Chưa làm: "&COUNTIF($I$6:$I$400,"Chưa làm") -> Chưa làm: 18 | G4: ="Bị chặn: "&COUNTIF($I$6:$I$400,"Bị chặn") -> Bị chặn: 2 | H4: ="Cần chốt: "&COUNTIF($I$6:$I$400,"Cần chốt") -> Cần chốt: 6 | I4: ="Chưa xác nhận: "&COUNTIF($I$6:$I$400,"Chưa xác nhận") -> Chưa xác nhận: 2 | J4: ="Cắt / hoãn: "&COUNTIF($I$6:$I$400,"Cắt / hoãn") -> Cắt / hoãn: 3 | K4: ="Tỷ lệ xong: "&TEXT(IFERROR(COUNTIF($I$6:$I$400,"Xong")/(COUNTA($C$6:$C$400)-COUNTIF($I$6:$I$400,"Cắt / hoãn")),0),"0%") -> Tỷ lệ xong: 24%
A5: STT | B5: Nhóm | C5: Mã | D5: Nội dung | E5: Sprint | F5: Phụ trách | G5: SP | H5: Ưu tiên | I5: Trạng thái | J5: Ghi chú / bằng chứng | K5: Nguồn | L5: Người xác nhận | M5: Ngày xong
A6: 1 | B6: Việc chặn & cần chốt | C6: CH-01 | D6: Nghĩa vụ xác thực SĐT Việt Nam theo NĐ 147/2024: mọi tài khoản hay chỉ tài khoản đăng nội dung công khai. | F6: Founder + Luật sư | I6: Cần chốt | J6: Hạn 21/09. Code đang ngầm chọn "không bắt buộc". Tinh gọn: Nếu bắt buộc cho mọi tài khoản thì dùng OTP của nhà cung cấp có sẵn (E3-S6 chỉ còn 2 SP, nhóm B) | K6: Doc 00 §9
A7: 2 | B7: Việc chặn & cần chốt | C7: MT-17 | D7: Chốt tên guard/decorator trust và RBAC (code: TrustLevelGuard/@MinTrustLevel; doc: TrustTierGuard/@MinTrust). | F7: TV1 | I7: Xong | J7: Hạn 21/09; chặn E2-S7. Chốt 24/09/2026: giữ tên code TrustLevelGuard/@MinTrustLevel; guard mới là RolesGuard/@Roles, thứ tự JwtAuthGuard → RolesGuard → TrustLevelGuard (D-07: role trước trust). Kế hoạch và nghiệm thu: .agent/specs/_changes/rbac-admin-shell/. | K7: Doc 00 · Kiểm tra code 18/09/2026 | M7: 24/09/2026
A8: 3 | B8: Việc chặn & cần chốt | C8: MT-16 | D8: user_status_enum 5 hay 8 giá trị (enum Postgres không xoá được giá trị). | F8: TV2 | I8: Cần chốt | J8: Hạn 02/10. | K8: Doc 00
A9: 4 | B9: Việc chặn & cần chốt | C9: PERM-MATRIX | D9: Vị trí PERMISSION_MATRIX máy đọc được (doc 00: packages/shared-types; doc 01: apps/api/…/authz/) + test describe.each T-1→T-5. | F9: TV1 | I9: Xong | J9: Hạn 21/09. Chốt 24/09/2026: packages/domain/src/permission-matrix.ts (STAFF_ROLES, SYSTEM_HEALTH_ROLES, PERMISSION_MATRIX), dùng chung cho RolesGuard ở API và menu/chặn route ở web admin; có unit test. | K9: Doc 00 §10 · Doc 01 §9.2 | M9: 24/09/2026
A10: 5 | B10: Việc chặn & cần chốt | C10: ADR-C9 | D10: Có tách schema identity_secret cho bảng xác thực mới không (ADR-0000 mục C9). | F10: Founder + TV1 | I10: Cần chốt | J10: Hạn ký 07/09 đã qua. Tinh gọn: Founder ký ADR; TV1 đề xuất phương án và viết migration nếu chốt tách schema | K10: docs/adr/0000
A11: 6 | B11: Việc chặn & cần chốt | C11: TOKEN-MOBILE | D11: Một cơ chế trả refresh token dùng chung cho web (cookie), mobile (SecureStore) và social login; đổi hợp đồng packages/contracts. | F11: TV2 | I11: Cần chốt | J11: Chặn E2-S3, E2-S4, E2-S9. Cổng phê duyệt: đổi packages dùng chung. Tinh gọn: Nhánh mobile (SecureStore) hoãn cùng E2-S9; chỉ cần chốt cookie cho web/PWA + Google, để hợp đồng mở sẵn cho bản native sau này | K11: Kiểm tra code 18/09/2026
A12: 7 | B12: Việc chặn & cần chốt | C12: BR-30 | D12: Nội dung Điều khoản / Chính sách quyền riêng tư và cơ chế consent_records (NĐ 13/2023 + Luật 91/2025). | F12: Founder + Luật sư | I12: Cần chốt | J12: Cần luật sư xác nhận. Tinh gọn: Founder soạn bản thảo mẫu, luật sư chỉ rà soát và ký xác nhận (gói pháp lý 55 triệu); vẫn phải theo Luật 91/2025 | K12: Doc 02 BR-30
A13: 8 | B13: Việc chặn & cần chốt | C13: ACC-APPLE-GOOGLE | D13: Xác nhận tài khoản Apple Developer tổ chức / D-U-N-S; tạo Google OAuth client (3 ID: web, iOS, Android). | F13: Founder + TV2 | I13: Chưa xác nhận | J13: Tinh gọn: Chỉ cần Google OAuth client cho web/PWA; không mua Apple Developer, D-U-N-S và 2 client iOS/Android thôi chặn vì E2-S4 bị cắt, bản native hoãn | K13: Doc 08 §6.3
A14: 9 | B14: Việc chặn & cần chốt | C14: OWNERS | D14: Gán người phụ trách cho T-10, T-11, T-12, T-14 trong ACTIVE_TASKS. | F14: TV1 | I14: Chưa làm | J14: Cột người phụ trách đang trống. Tinh gọn: Gán theo đội tinh gọn: T-10, T-11, T-12 cho TV2; T-14 cho TV1; T-11 chỉ còn Google | K14: .agent/memory/ACTIVE_TASKS.md
A15: 10 | B15: Việc chặn & cần chốt | C15: INFRA-MAIL | D15: Nối mail client (SMTP → Mailpit) dùng chung cho E2-S1 và E2-S6. | F15: TV1 | I15: Xong | J15: Xong 24/09/2026: MailModule gửi qua SMTP (mặc định Mailpit), chặn người nhận theo MAIL_ALLOWED_DOMAINS cho staging, không ghi địa chỉ email vào log (e2e mail.e2e.spec.ts gửi thật và đọc lại từ Mailpit). | K15: Kiểm tra code 18/09/2026 | M15: 24/09/2026
A16: 11 | B16: Việc chặn & cần chốt | C16: INFRA-REDIS | D16: Nối Redis client (ioredis / BullMQ) cho rate limit E2-S10 và job trust:recompute (T-13). | F16: TV1 | I16: Xong | J16: Xong 24/09/2026: RedisModule có hai client (cache 6381, queue 6380 cấu hình sẵn cho BullMQ), kết nối lười, log khi mất và khi khôi phục kết nối, đóng sạch khi tắt app (enableShutdownHooks). Hàng đợi BullMQ tạo cùng E7-S1. | K16: Kiểm tra code 18/09/2026 | M16: 24/09/2026
A17: 12 | B17: Việc chặn & cần chốt | C17: SEC-JWT-LOG | D17: Vá lỗi ghi khoá riêng JWT ra log debug khi thiếu JWT_PRIVATE_KEY (auth.service.ts:107), trước khi bật log tập trung. | F17: TV2 | I17: Chưa làm | J17: Lỗi bảo mật. | K17: Kiểm tra code 18/09/2026
A18: 13 | B18: Việc chặn & cần chốt | C18: T-14 | D18: Dựng Playwright ở apps/web-client-side/e2e/, chạy cả WebKit. | F18: TV1 | I18: Chưa làm | J18: Ba bug chỉ-có-ở-client đã lọt lưới. Tinh gọn: Không có QA thường trực: TV1 dựng khung, mỗi thành viên viết E2E cho chức năng của mình; QA thuê ngoài chỉ chạy 2 đợt trước beta và trước ra mắt | K18: .agent/memory/ACTIVE_TASKS.md
A19: 14 | B19: Story | C19: E2-S1 | D19: Đăng ký email + xác minh email | E19: L1 | F19: TV2 | G19: 8 | H19: MUST | I19: Một phần | J19: Đăng ký có nhưng cấp phiên + T1 ngay; chưa có token xác minh, endpoint verify, gửi mail (Mailpit đã chạy). Tinh gọn: Xác minh chỉ làm trên web/PWA; màn web do TV2 làm (MK-AUTH-02) | K19: Kiểm tra code 18/09/2026
A20: 15 | B20: Story | C20: E2-S2 | D20: JWT access 15 phút + refresh 30 ngày xoay vòng, phát hiện tái sử dụng | E20: L1 | F20: TV2 | G20: 8 | H20: MUST | I20: Xong | J20: Access 15 phút + refresh 30 ngày xoay vòng; test e2e "dùng lại token → thu hồi cả họ" (auth.e2e.spec.ts:323). | K20: Kiểm tra code 18/09/2026
